Workbook

Sheet Employee KPI Report
A1: Department KPI Dashboard - Employee Learning KPI Report
A2: FY: Apr 2025 - Mar 2026 | Date Range: 01-Apr-2025 to 31-Mar-2026
A4: S.No | B4: Employee ID | C4: Employee Name | D4: Date of Joining | E4: APRIL | H4: MAY | K4: JUNE | N4: JULY | Q4: AUGUST | T4: SEPTEMBER | W4: OCTOBER | Z4: NOVEMBER | AC4: DECEMBER | AF4: JANUARY | AI4: FEBRUARY | AL4: MARCH | AO4: Total Hours | AP4: Target Hours | AQ4: Balance | AR4: KPI % | AS4: Learning Compliance | AT4: Department | AU4: Manager | AV4: Attendance %
E5: Date | F5: Actual | G5: Max Hours | H5: Date | I5: Actual | J5: Max Hours | K5: Date | L5: Actual | M5: Max Hours | N5: Date | O5: Actual | P5: Max Hours | Q5: Date | R5: Actual | S5: Max Hours | T5: Date | U5: Actual | V5: Max Hours | W5: Date | X5: Actual | Y5: Max Hours | Z5: Date | AA5: Actual | AB5: Max Hours | AC5: Date | AD5: Actual | AE5: Max Hours | AF5: Date | AG5: Actual | AH5: Max Hours | AI5: Date | AJ5: Actual | AK5: Max Hours | AL5: Date | AM5: Actual | AN5: Max Hours
A6: 1 | B6: 011 | C6: Mariyaruban Mariyakilaimans | AO6: 0 | AP6: 16 | AQ6: 16.0 Hours Remaining | AR6: 0.0% | AS6: Critical | AT6: Accounts | AU6: Arunachalam Palaniappan | AV6: 0.0%
A7: 2 | B7: 029 | C7: Jayesh Nitin Patel | AO7: 0 | AP7: 16 | AQ7: 16.0 Hours Remaining | AR7: 0.0% | AS7: Critical | AT7: Accounts | AU7: Arunachalam Palaniappan | AV7: 0.0%
A8: 3 | B8: 12 | C8: Nandinee Kapilesh sharma | AO8: 0 | AP8: 16 | AQ8: 16.0 Hours Remaining | AR8: 0.0% | AS8: Critical | AT8: Accounts | AU8: Team Manager | AV8: 0.0%
A9: 4 | B9: 20 | C9: Kumaresh B | AO9: 0 | AP9: 16 | AQ9: 16.0 Hours Remaining | AR9: 0.0% | AS9: Critical | AT9: Accounts | AU9: Team Manager | AV9: 0.0%
A10: 5 | B10: 67 | C10: Rambabu K | AO10: 0 | AP10: 16 | AQ10: 16.0 Hours Remaining | AR10: 0.0% | AS10: Critical | AT10: Accounts | AU10: Arunachalam Palaniappan | AV10: 0.0%
A11: 6 | B11: 68 | C11: Prathap Gundapa | AO11: 0 | AP11: 16 | AQ11: 16.0 Hours Remaining | AR11: 0.0% | AS11: Critical | AT11: Accounts | AU11: Arunachalam Palaniappan | AV11: 0.0%
A12: 7 | B12: 95 | C12: Arunachalam Palaniappan | AO12: 0 | AP12: 16 | AQ12: 16.0 Hours Remaining | AR12: 0.0% | AS12: Critical | AT12: Accounts | AU12: Team Manager | AV12: 0.0%
C13: Accounts Subtotal | F13: =SUM(F6:F12) | G13: =SUM(G6:G12) | I13: =SUM(I6:I12) | J13: =SUM(J6:J12) | L13: =SUM(L6:L12) | M13: =SUM(M6:M12) | O13: =SUM(O6:O12) | P13: =SUM(P6:P12) | R13: =SUM(R6:R12) | S13: =SUM(S6:S12) | U13: =SUM(U6:U12) | V13: =SUM(V6:V12) | X13: =SUM(X6:X12) | Y13: =SUM(Y6:Y12) | AA13: =SUM(AA6:AA12) | AB13: =SUM(AB6:AB12) | AD13: =SUM(AD6:AD12) | AE13: =SUM(AE6:AE12) | AG13: =SUM(AG6:AG12) | AH13: =SUM(AH6:AH12) | AJ13: =SUM(AJ6:AJ12) | AK13: =SUM(AK6:AK12) | AM13: =SUM(AM6:AM12) | AN13: =SUM(AN6:AN12) | AO13: =SUM(AO6:AO12) | AP13: =SUM(AP6:AP12) | AQ13: =SUM(AQ6:AQ12) | AR13: =IF(AP13>0, AO13/AP13, 0) | AS13: =IF(AR13>=1.0, "Achieved", IF(AR13>=0.75, "Good", IF(AR13>=0.5, "Moderate", IF(AR13>=0.25, "Low", "Critical")))) | AT13: Accounts | AV13: =AVERAGE(AV6:AV12)
A14: 8 | B14: 003 | C14: Megha Lakshmi Murugamani | AO14: 0 | AP14: 16 | AQ14: 16.0 Hours Remaining | AR14: 0.0% | AS14: Critical | AT14: CRM | AU14: Prakash Padukhone Muthiah | AV14: 0.0%
A15: 9 | B15: 49 | C15: Roopa R | AO15: 0 | AP15: 16 | AQ15: 16.0 Hours Remaining | AR15: 0.0% | AS15: Critical | AT15: CRM | AU15: Prakash Padukhone Muthiah | AV15: 0.0%
C16: CRM Subtotal | F16: =SUM(F14:F15) | G16: =SUM(G14:G15) | I16: =SUM(I14:I15) | J16: =SUM(J14:J15) | L16: =SUM(L14:L15) | M16: =SUM(M14:M15) | O16: =SUM(O14:O15) | P16: =SUM(P14:P15) | R16: =SUM(R14:R15) | S16: =SUM(S14:S15) | U16: =SUM(U14:U15) | V16: =SUM(V14:V15) | X16: =SUM(X14:X15) | Y16: =SUM(Y14:Y15) | AA16: =SUM(AA14:AA15) | AB16: =SUM(AB14:AB15) | AD16: =SUM(AD14:AD15) | AE16: =SUM(AE14:AE15) | AG16: =SUM(AG14:AG15) | AH16: =SUM(AH14:AH15) | AJ16: =SUM(AJ14:AJ15) | AK16: =SUM(AK14:AK15) | AM16: =SUM(AM14:AM15) | AN16: =SUM(AN14:AN15) | AO16: =SUM(AO14:AO15) | AP16: =SUM(AP14:AP15) | AQ16: =SUM(AQ14:AQ15) | AR16: =IF(AP16>0, AO16/AP16, 0) | AS16: =IF(AR16>=1.0, "Achieved", IF(AR16>=0.75, "Good", IF(AR16>=0.5, "Moderate", IF(AR16>=0.25, "Low", "Critical")))) | AT16: CRM | AV16: =AVERAGE(AV14:AV15)
A17: 10 | B17: 108 | C17: Ramani Balan | AO17: 0 | AP17: 16 | AQ17: 16.0 Hours Remaining | AR17: 0.0% | AS17: Critical | AT17: Casting | AU17: R Rathina Kumar | AV17: 0.0%
A18: 11 | B18: 81 | C18: Balakumar N | AO18: 0 | AP18: 16 | AQ18: 16.0 Hours Remaining | AR18: 0.0% | AS18: Critical | AT18: Casting | AU18: R Rathina Kumar | AV18: 0.0%
C19: Casting Subtotal | F19: =SUM(F17:F18) | G19: =SUM(G17:G18) | I19: =SUM(I17:I18) | J19: =SUM(J17:J18) | L19: =SUM(L17:L18) | M19: =SUM(M17:M18) | O19: =SUM(O17:O18) | P19: =SUM(P17:P18) | R19: =SUM(R17:R18) | S19: =SUM(S17:S18) | U19: =SUM(U17:U18) | V19: =SUM(V17:V18) | X19: =SUM(X17:X18) | Y19: =SUM(Y17:Y18) | AA19: =SUM(AA17:AA18) | AB19: =SUM(AB17:AB18) | AD19: =SUM(AD17:AD18) | AE19: =SUM(AE17:AE18) | AG19: =SUM(AG17:AG18) | AH19: =SUM(AH17:AH18) | AJ19: =SUM(AJ17:AJ18) | AK19: =SUM(AK17:AK18) | AM19: =SUM(AM17:AM18) | AN19: =SUM(AN17:AN18) | AO19: =SUM(AO17:AO18) | AP19: =SUM(AP17:AP18) | AQ19: =SUM(AQ17:AQ18) | AR19: =IF(AP19>0, AO19/AP19, 0) | AS19: =IF(AR19>=1.0, "Achieved", IF(AR19>=0.75, "Good", IF(AR19>=0.5, "Moderate", IF(AR19>=0.25, "Low", "Critical")))) | AT19: Casting | AV19: =AVERAGE(AV17:AV18)
A20: 12 | B20: 11 | C20: Rajeshwari Ganeshkumar | AO20: 0 | AP20: 16 | AQ20: 16.0 Hours Remaining | AR20: 0.0% | AS20: Critical | AT20: Commercial | AU20: Prakash Padukhone Muthiah | AV20: 0.0%
A21: 13 | B21: 33 | C21: Vivek R | AO21: 0 | AP21: 16 | AQ21: 16.0 Hours Remaining | AR21: 0.0% | AS21: Critical | AT21: Commercial | AU21: Rajeshwari Ganeshkumar | AV21: 0.0%
A22: 14 | B22: 82 | C22: Sathishkumar Narayanappa | AO22: 0 | AP22: 16 | AQ22: 16.0 Hours Remaining | AR22: 0.0% | AS22: Critical | AT22: Commercial | AU22: Rajeshwari Ganeshkumar | AV22: 0.0%
C23: Commercial Subtotal | F23: =SUM(F20:F22) | G23: =SUM(G20:G22) | I23: =SUM(I20:I22) | J23: =SUM(J20:J22) | L23: =SUM(L20:L22) | M23: =SUM(M20:M22) | O23: =SUM(O20:O22) | P23: =SUM(P20:P22) | R23: =SUM(R20:R22) | S23: =SUM(S20:S22) | U23: =SUM(U20:U22) | V23: =SUM(V20:V22) | X23: =SUM(X20:X22) | Y23: =SUM(Y20:Y22) | AA23: =SUM(AA20:AA22) | AB23: =SUM(AB20:AB22) | AD23: =SUM(AD20:AD22) | AE23: =SUM(AE20:AE22) | AG23: =SUM(AG20:AG22) | AH23: =SUM(AH20:AH22) | AJ23: =SUM(AJ20:AJ22) | AK23: =SUM(AK20:AK22) | AM23: =SUM(AM20:AM22) | AN23: =SUM(AN20:AN22) | AO23: =SUM(AO20:AO22) | AP23: =SUM(AP20:AP22) | AQ23: =SUM(AQ20:AQ22) | AR23: =IF(AP23>0, AO23/AP23, 0) | AS23: =IF(AR23>=1.0, "Achieved", IF(AR23>=0.75, "Good", IF(AR23>=0.5, "Moderate", IF(AR23>=0.25, "Low", "Critical")))) | AT23: Commercial | AV23: =AVERAGE(AV20:AV22)
A24: 15 | B24: 70 | C24: Mohan S | AO24: 0 | AP24: 16 | AQ24: 16.0 Hours Remaining | AR24: 0.0% | AS24: Critical | AT24: Driver | AU24: Sakthivel Muthu | AV24: 0.0%
C25: Driver Subtotal | F25: =SUM(F24:F24) | G25: =SUM(G24:G24) | I25: =SUM(I24:I24) | J25: =SUM(J24:J24) | L25: =SUM(L24:L24) | M25: =SUM(M24:M24) | O25: =SUM(O24:O24) | P25: =SUM(P24:P24) | R25: =SUM(R24:R24) | S25: =SUM(S24:S24) | U25: =SUM(U24:U24) | V25: =SUM(V24:V24) | X25: =SUM(X24:X24) | Y25: =SUM(Y24:Y24) | AA25: =SUM(AA24:AA24) | AB25: =SUM(AB24:AB24) | AD25: =SUM(AD24:AD24) | AE25: =SUM(AE24:AE24) | AG25: =SUM(AG24:AG24) | AH25: =SUM(AH24:AH24) | AJ25: =SUM(AJ24:AJ24) | AK25: =SUM(AK24:AK24) | AM25: =SUM(AM24:AM24) | AN25: =SUM(AN24:AN24) | AO25: =SUM(AO24:AO24) | AP25: =SUM(AP24:AP24) | AQ25: =SUM(AQ24:AQ24) | AR25: =IF(AP25>0, AO25/AP25, 0) | AS25: =IF(AR25>=1.0, "Achieved", IF(AR25>=0.75, "Good", IF(AR25>=0.5, "Moderate", IF(AR25>=0.25, "Low", "Critical")))) | AT25: Driver | AV25: =AVERAGE(AV24:AV24)
A26: 16 | B26: 41 | C26: Radhalakshmi S | AO26: 0 | AP26: 16 | AQ26: 16.0 Hours Remaining | AR26: 0.0% | AS26: Critical | AT26: HR | AU26: Manasa R | AV26: 0.0%
A27: 17 | B27: 73 | C27: P Nalini | AO27: 0 | AP27: 16 | AQ27: 16.0 Hours Remaining | AR27: 0.0% | AS27: Critical | AT27: HR | AU27: Manasa R | AV27: 0.0%
A28: 18 | B28: 74 | C28: Manasa R | AO28: 0 | AP28: 16 | AQ28: 16.0 Hours Remaining | AR28: 0.0% | AS28: Critical | AT28: HR | AU28: Prakash Padukhone Muthiah | AV28: 0.0%
C29: HR Subtotal | F29: =SUM(F26:F28) | G29: =SUM(G26:G28) | I29: =SUM(I26:I28) | J29: =SUM(J26:J28) | L29: =SUM(L26:L28) | M29: =SUM(M26:M28) | O29: =SUM(O26:O28) | P29: =SUM(P26:P28) | R29: =SUM(R26:R28) | S29: =SUM(S26:S28) | U29: =SUM(U26:U28) | V29: =SUM(V26:V28) | X29: =SUM(X26:X28) | Y29: =SUM(Y26:Y28) | AA29: =SUM(AA26:AA28) | AB29: =SUM(AB26:AB28) | AD29: =SUM(AD26:AD28) | AE29: =SUM(AE26:AE28) | AG29: =SUM(AG26:AG28) | AH29: =SUM(AH26:AH28) | AJ29: =SUM(AJ26:AJ28) | AK29: =SUM(AK26:AK28) | AM29: =SUM(AM26:AM28) | AN29: =SUM(AN26:AN28) | AO29: =SUM(AO26:AO28) | AP29: =SUM(AP26:AP28) | AQ29: =SUM(AQ26:AQ28) | AR29: =IF(AP29>0, AO29/AP29, 0) | AS29: =IF(AR29>=1.0, "Achieved", IF(AR29>=0.75, "Good", IF(AR29>=0.5, "Moderate", IF(AR29>=0.25, "Low", "Critical")))) | AT29: HR | AV29: =AVERAGE(AV26:AV28)
A30: 19 | B30: 017 | C30: Saravana Hanumanthappa | AO30: 0 | AP30: 16 | AQ30: 16.0 Hours Remaining | AR30: 0.0% | AS30: Critical | AT30: IT Support | AU30: Manasa R | AV30: 0.0%
C31: IT Support Subtotal | F31: =SUM(F30:F30) | G31: =SUM(G30:G30) | I31: =SUM(I30:I30) | J31: =SUM(J30:J30) | L31: =SUM(L30:L30) | M31: =SUM(M30:M30) | O31: =SUM(O30:O30) | P31: =SUM(P30:P30) | R31: =SUM(R30:R30) | S31: =SUM(S30:S30) | U31: =SUM(U30:U30) | V31: =SUM(V30:V30) | X31: =SUM(X30:X30) | Y31: =SUM(Y30:Y30) | AA31: =SUM(AA30:AA30) | AB31: =SUM(AB30:AB30) | AD31: =SUM(AD30:AD30) | AE31: =SUM(AE30:AE30) | AG31: =SUM(AG30:AG30) | AH31: =SUM(AH30:AH30) | AJ31: =SUM(AJ30:AJ30) | AK31: =SUM(AK30:AK30) | AM31: =SUM(AM30:AM30) | AN31: =SUM(AN30:AN30) | AO31: =SUM(AO30:AO30) | AP31: =SUM(AP30:AP30) | AQ31: =SUM(AQ30:AQ30) | AR31: =IF(AP31>0, AO31/AP31, 0) | AS31: =IF(AR31>=1.0, "Achieved", IF(AR31>=0.75, "Good", IF(AR31>=0.5, "Moderate", IF(AR31>=0.25, "Low", "Critical")))) | AT31: IT Support | AV31: =AVERAGE(AV30:AV30)
A32: 20 | B32: 021 | C32: C Mohankumar | AO32: 0 | AP32: 16 | AQ32: 16.0 Hours Remaining | AR32: 0.0% | AS32: Critical | AT32: Maintenance | AU32: Manasa R | AV32: 0.0%
C33: Maintenance Subtotal | F33: =SUM(F32:F32) | G33: =SUM(G32:G32) | I33: =SUM(I32:I32) | J33: =SUM(J32:J32) | L33: =SUM(L32:L32) | M33: =SUM(M32:M32) | O33: =SUM(O32:O32) | P33: =SUM(P32:P32) | R33: =SUM(R32:R32) | S33: =SUM(S32:S32) | U33: =SUM(U32:U32) | V33: =SUM(V32:V32) | X33: =SUM(X32:X32) | Y33: =SUM(Y32:Y32) | AA33: =SUM(AA32:AA32) | AB33: =SUM(AB32:AB32) | AD33: =SUM(AD32:AD32) | AE33: =SUM(AE32:AE32) | AG33: =SUM(AG32:AG32) | AH33: =SUM(AH32:AH32) | AJ33: =SUM(AJ32:AJ32) | AK33: =SUM(AK32:AK32) | AM33: =SUM(AM32:AM32) | AN33: =SUM(AN32:AN32) | AO33: =SUM(AO32:AO32) | AP33: =SUM(AP32:AP32) | AQ33: =SUM(AQ32:AQ32) | AR33: =IF(AP33>0, AO33/AP33, 0) | AS33: =IF(AR33>=1.0, "Achieved", IF(AR33>=0.75, "Good", IF(AR33>=0.5, "Moderate", IF(AR33>=0.25, "Low", "Critical")))) | AT33: Maintenance | AV33: =AVERAGE(AV32:AV32)
A34: 21 | B34: MGR001 | C34: Team Manager | AO34: 0 | AP34: 16 | AQ34: 16.0 Hours Remaining | AR34: 0.0% | AS34: Critical | AT34: Management | AV34: 0.0%
A35: 22 | B35: SGS-KET | C35: Ketan BC | AO35: 0 | AP35: 16 | AQ35: 16.0 Hours Remaining | AR35: 0.0% | AS35: Critical | AT35: Management | AU35: Team Manager | AV35: 0.0%
A36: 23 | B36: SGS-NIT | C36: Nitin R Patel | AO36: 0 | AP36: 16 | AQ36: 16.0 Hours Remaining | AR36: 0.0% | AS36: Critical | AT36: Management | AU36: Team Manager | AV36: 0.0%
C37: Management Subtotal | F37: =SUM(F34:F36) | G37: =SUM(G34:G36) | I37: =SUM(I34:I36) | J37: =SUM(J34:J36) | L37: =SUM(L34:L36) | M37: =SUM(M34:M36) | O37: =SUM(O34:O36) | P37: =SUM(P34:P36) | R37: =SUM(R34:R36) | S37: =SUM(S34:S36) | U37: =SUM(U34:U36) | V37: =SUM(V34:V36) | X37: =SUM(X34:X36) | Y37: =SUM(Y34:Y36) | AA37: =SUM(AA34:AA36) | AB37: =SUM(AB34:AB36) | AD37: =SUM(AD34:AD36) | AE37: =SUM(AE34:AE36) | AG37: =SUM(AG34:AG36) | AH37: =SUM(AH34:AH36) | AJ37: =SUM(AJ34:AJ36) | AK37: =SUM(AK34:AK36) | AM37: =SUM(AM34:AM36) | AN37: =SUM(AN34:AN36) | AO37: =SUM(AO34:AO36) | AP37: =SUM(AP34:AP36) | AQ37: =SUM(AQ34:AQ36) | AR37: =IF(AP37>0, AO37/AP37, 0) | AS37: =IF(AR37>=1.0, "Achieved", IF(AR37>=0.75, "Good", IF(AR37>=0.5, "Moderate", IF(AR37>=0.25, "Low", "Critical")))) | AT37: Management | AV37: =AVERAGE(AV34:AV36)
A38: 24 | B38: 87 | C38: Ankul Kumar | AO38: 0 | AP38: 16 | AQ38: 16.0 Hours Remaining | AR38: 0.0% | AS38: Critical | AT38: Marketing | AU38: Prakash Padukhone Muthiah | AV38: 0.0%
C39: Marketing Subtotal | F39: =SUM(F38:F38) | G39: =SUM(G38:G38) | I39: =SUM(I38:I38) | J39: =SUM(J38:J38) | L39: =SUM(L38:L38) | M39: =SUM(M38:M38) | O39: =SUM(O38:O38) | P39: =SUM(P38:P38) | R39: =SUM(R38:R38) | S39: =SUM(S38:S38) | U39: =SUM(U38:U38) | V39: =SUM(V38:V38) | X39: =SUM(X38:X38) | Y39: =SUM(Y38:Y38) | AA39: =SUM(AA38:AA38) | AB39: =SUM(AB38:AB38) | AD39: =SUM(AD38:AD38) | AE39: =SUM(AE38:AE38) | AG39: =SUM(AG38:AG38) | AH39: =SUM(AH38:AH38) | AJ39: =SUM(AJ38:AJ38) | AK39: =SUM(AK38:AK38) | AM39: =SUM(AM38:AM38) | AN39: =SUM(AN38:AN38) | AO39: =SUM(AO38:AO38) | AP39: =SUM(AP38:AP38) | AQ39: =SUM(AQ38:AQ38) | AR39: =IF(AP39>0, AO39/AP39, 0) | AS39: =IF(AR39>=1.0, "Achieved", IF(AR39>=0.75, "Good", IF(AR39>=0.5, "Moderate", IF(AR39>=0.25, "Low", "Critical")))) | AT39: Marketing | AV39: =AVERAGE(AV38:AV38)
A40: 25 | B40: 007 | C40: Naveenkumar M | AO40: 0 | AP40: 16 | AQ40: 16.0 Hours Remaining | AR40: 0.0% | AS40: Critical | AT40: NPD | AU40: Prakash Padukhone Muthiah | AV40: 0.0%
A41: 26 | B41: 025 | C41: Nandhakumar G | AO41: 0 | AP41: 16 | AQ41: 16.0 Hours Remaining | AR41: 0.0% | AS41: Critical | AT41: NPD | AU41: Naveenkumar M | AV41: 0.0%
...

Sheet Monthly Learning Summary
A1: Monthly Learning Performance Summary
A3: Month | B3: Target Hours | C3: Actual Hours | D3: Achievement % | E3: Attendance % | F3: Training Count | G3: Monthly Trends
A4: April | B4: 117 | C4: 0 | D4: =IF(B4>0, C4/B4, 0) | E4: 1 | F4: 0 | G4: —
A5: May | B5: 117 | C5: 0 | D5: =IF(B5>0, C5/B5, 0) | E5: 1 | F5: 0 | G5: =IF(C4>0, (C5-C4)/C4, 0)
A6: June | B6: 117 | C6: 0 | D6: =IF(B6>0, C6/B6, 0) | E6: 1 | F6: 0 | G6: =IF(C5>0, (C6-C5)/C5, 0)
A7: July | B7: 117 | C7: 0 | D7: =IF(B7>0, C7/B7, 0) | E7: 1 | F7: 0 | G7: =IF(C6>0, (C7-C6)/C6, 0)
A8: August | B8: 117 | C8: 0 | D8: =IF(B8>0, C8/B8, 0) | E8: 1 | F8: 0 | G8: =IF(C7>0, (C8-C7)/C7, 0)
A9: September | B9: 117 | C9: 0 | D9: =IF(B9>0, C9/B9, 0) | E9: 1 | F9: 0 | G9: =IF(C8>0, (C9-C8)/C8, 0)
A10: October | B10: 117 | C10: 0 | D10: =IF(B10>0, C10/B10, 0) | E10: 1 | F10: 0 | G10: =IF(C9>0, (C10-C9)/C9, 0)
A11: November | B11: 117 | C11: 0 | D11: =IF(B11>0, C11/B11, 0) | E11: 1 | F11: 0 | G11: =IF(C10>0, (C11-C10)/C10, 0)
A12: December | B12: 117 | C12: 0 | D12: =IF(B12>0, C12/B12, 0) | E12: 1 | F12: 0 | G12: =IF(C11>0, (C12-C11)/C11, 0)
A13: January | B13: 117 | C13: 0 | D13: =IF(B13>0, C13/B13, 0) | E13: 1 | F13: 0 | G13: =IF(C12>0, (C13-C12)/C12, 0)
A14: February | B14: 117 | C14: 0 | D14: =IF(B14>0, C14/B14, 0) | E14: 1 | F14: 0 | G14: =IF(C13>0, (C14-C13)/C13, 0)
A15: March | B15: 117 | C15: 0 | D15: =IF(B15>0, C15/B15, 0) | E15: 1 | F15: 0 | G15: =IF(C14>0, (C15-C14)/C14, 0)
A16: Total | B16: =SUM(B4:B15) | C16: =SUM(C4:C15) | D16: =IF(B16>0, C16/B16, 0) | E16: =AVERAGE(E4:E15) | F16: =SUM(F4:F15)

Sheet Training Attendance Summary
A1: Training Session Attendance Summary
A3: Training Name | B3: Department | C3: Training Date | D3: Enrolled Count | E3: Present Count | F3: Absent Count | G3: Late Count | H3: Attendance % | I3: Trainer | J3: Duration (Hours)
A4: Total / Average | D4: =SUM(D4:D3) | E4: =SUM(E4:E3) | F4: =SUM(F4:F3) | G4: =SUM(G4:G3) | H4: =IF(D4>0, (E4+G4)/D4, 1.0) | J4: =SUM(J4:J3)

Sheet Department KPI Analytics
A1: ORGANIZATION LEARNING & KPI ANALYTICS DASHBOARD
A2: Executive Overview & Department Contribution Analysis
A4: Interactive Filters (Select values to dynamically update the dashboard)
B5: Financial Year | D5: Quarter | E5: Month | G5: Department | J5: Training Category
B6: 2025-2026 | D6: All | E6: All | G6: All | J6: All
A10: TOTAL EMPLOYEES | C10: TOTAL TARGET HOURS | E10: TOTAL ACTUAL HOURS | G10: TOTAL REMAINING HOURS | I10: OVERALL ACHIEVEMENT %
A11: =COUNTIFS(Employee_KPI_Summary!$F$6:$F$93, ">0") | C11: =SUM(Employee_KPI_Summary!$F$6:$F$93) | E11: =SUM(Employee_KPI_Summary!$G$6:$G$93) | G11: =SUM(Employee_KPI_Summary!$H$6:$H$93) | I11: =IF(C11>0, E11/C11, 0)
A12: LEARNING COMPLIANCE % | C12: TRAININGS CONDUCTED | E12: TOTAL ATTENDANCE % | G12: TOP PERFORMING DEPT | I12: LOWEST PERFORMING DEPT
A13: =IF(COUNTIFS(Employee_KPI_Summary!$F$6:$F$93, ">0")>0, COUNTIFS(Employee_KPI_Summary!$F$6:$F$93, ">0", Employee_KPI_Summary!$I$6:$I$93, ">=1.0")/COUNTIFS(Employee_KPI_Summary!$F$6:$F$93, ">0"), 1.0) | C13: =SUM(Raw_Attendance_Data!$P$2:$P$2) | E13: =IF(SUM(Employee_KPI_Summary!$K$6:$K$93)>0, SUM(Employee_KPI_Summary!$J$6:$J$93)/SUM(Employee_KPI_Summary!$K$6:$K$93), 1.0) | G13: =INDEX(B17:B33, MATCH(MAX(G17:G33), G17:G33, 0)) | I13: =INDEX(B17:B33, MATCH(MIN(K17:K33), K17:K33, 0))
A15: DEPARTMENT CONTRIBUTION & KPI SUMMARY
A16: S.No | B16: Department | C16: Employees | D16: Target Hours | E16: Actual Hours | F16: Remaining Hours | G16: Achievement % | H16: Attendance % | I16: KPI Status | J16: Rank Score | K16: Filtered Achievement
A17: =ROW() - 16 | B17: Accounts | C17: =COUNTIFS(Employee_KPI_Summary!$D$6:$D$93, B17, Employee_KPI_Summary!$F$6:$F$93, ">0") | D17: =SUMIFS(Employee_KPI_Summary!$F$6:$F$93, Employee_KPI_Summary!$D$6:$D$93, B17) | E17: =SUMIFS(Employee_KPI_Summary!$G$6:$G$93, Employee_KPI_Summary!$D$6:$D$93, B17) | F17: =SUMIFS(Employee_KPI_Summary!$H$6:$H$93, Employee_KPI_Summary!$D$6:$D$93, B17) | G17: =IF(D17>0, E17/D17, 0) | H17: =IF(SUMIFS(Employee_KPI_Summary!$K$6:$K$93, Employee_KPI_Summary!$D$6:$D$93, B17)>0, SUMIFS(Employee_KPI_Summary!$J$6:$J$93, Employee_KPI_Summary!$D$6:$D$93, B17)/SUMIFS(Employee_KPI_Summary!$K$6:$K$93, Employee_KPI_Summary!$D$6:$D$93, B17), 1.0) | I17: =IF(G17>=1.0, "Achieved", IF(G17>=0.75, "Good", IF(G17>=0.5, "Moderate", IF(G17>=0.25, "Low", "Critical")))) | J17: =G17+(1000-ROW())/1000000 | K17: =IF(C17>0, G17+ROW()/1000000, 9.99)
A18: =ROW() - 16 | B18: Casting | C18: =COUNTIFS(Employee_KPI_Summary!$D$6:$D$93, B18, Employee_KPI_Summary!$F$6:$F$93, ">0") | D18: =SUMIFS(Employee_KPI_Summary!$F$6:$F$93, Employee_KPI_Summary!$D$6:$D$93, B18) | E18: =SUMIFS(Employee_KPI_Summary!$G$6:$G$93, Employee_KPI_Summary!$D$6:$D$93, B18) | F18: =SUMIFS(Employee_KPI_Summary!$H$6:$H$93, Employee_KPI_Summary!$D$6:$D$93, B18) | G18: =IF(D18>0, E18/D18, 0) | H18: =IF(SUMIFS(Employee_KPI_Summary!$K$6:$K$93, Employee_KPI_Summary!$D$6:$D$93, B18)>0, SUMIFS(Employee_KPI_Summary!$J$6:$J$93, Employee_KPI_Summary!$D$6:$D$93, B18)/SUMIFS(Employee_KPI_Summary!$K$6:$K$93, Employee_KPI_Summary!$D$6:$D$93, B18), 1.0) | I18: =IF(G18>=1.0, "Achieved", IF(G18>=0.75, "Good", IF(G18>=0.5, "Moderate", IF(G18>=0.25, "Low", "Critical")))) | J18: =G18+(1000-ROW())/1000000 | K18: =IF(C18>0, G18+ROW()/1000000, 9.99)
A19: =ROW() - 16 | B19: Commercial | C19: =COUNTIFS(Employee_KPI_Summary!$D$6:$D$93, B19, Employee_KPI_Summary!$F$6:$F$93, ">0") | D19: =SUMIFS(Employee_KPI_Summary!$F$6:$F$93, Employee_KPI_Summary!$D$6:$D$93, B19) | E19: =SUMIFS(Employee_KPI_Summary!$G$6:$G$93, Employee_KPI_Summary!$D$6:$D$93, B19) | F19: =SUMIFS(Employee_KPI_Summary!$H$6:$H$93, Employee_KPI_Summary!$D$6:$D$93, B19) | G19: =IF(D19>0, E19/D19, 0) | H19: =IF(SUMIFS(Employee_KPI_Summary!$K$6:$K$93, Employee_KPI_Summary!$D$6:$D$93, B19)>0, SUMIFS(Employee_KPI_Summary!$J$6:$J$93, Employee_KPI_Summary!$D$6:$D$93, B19)/SUMIFS(Employee_KPI_Summary!$K$6:$K$93, Employee_KPI_Summary!$D$6:$D$93, B19), 1.0) | I19: =IF(G19>=1.0, "Achieved", IF(G19>=0.75, "Good", IF(G19>=0.5, "Moderate", IF(G19>=0.25, "Low", "Critical")))) | J19: =G19+(1000-ROW())/1000000 | K19: =IF(C19>0, G19+ROW()/1000000, 9.99)
A20: =ROW() - 16 | B20: CRM | C20: =COUNTIFS(Employee_KPI_Summary!$D$6:$D$93, B20, Employee_KPI_Summary!$F$6:$F$93, ">0") | D20: =SUMIFS(Employee_KPI_Summary!$F$6:$F$93, Employee_KPI_Summary!$D$6:$D$93, B20) | E20: =SUMIFS(Employee_KPI_Summary!$G$6:$G$93, Employee_KPI_Summary!$D$6:$D$93, B20) | F20: =SUMIFS(Employee_KPI_Summary!$H$6:$H$93, Employee_KPI_Summary!$D$6:$D$93, B20) | G20: =IF(D20>0, E20/D20, 0) | H20: =IF(SUMIFS(Employee_KPI_Summary!$K$6:$K$93, Employee_KPI_Summary!$D$6:$D$93, B20)>0, SUMIFS(Employee_KPI_Summary!$J$6:$J$93, Employee_KPI_Summary!$D$6:$D$93, B20)/SUMIFS(Employee_KPI_Summary!$K$6:$K$93, Employee_KPI_Summary!$D$6:$D$93, B20), 1.0) | I20: =IF(G20>=1.0, "Achieved", IF(G20>=0.75, "Good", IF(G20>=0.5, "Moderate", IF(G20>=0.25, "Low", "Critical")))) | J20: =G20+(1000-ROW())/1000000 | K20: =IF(C20>0, G20+ROW()/1000000, 9.99)
A21: =ROW() - 16 | B21: Driver | C21: =COUNTIFS(Employee_KPI_Summary!$D$6:$D$93, B21, Employee_KPI_Summary!$F$6:$F$93, ">0") | D21: =SUMIFS(Employee_KPI_Summary!$F$6:$F$93, Employee_KPI_Summary!$D$6:$D$93, B21) | E21: =SUMIFS(Employee_KPI_Summary!$G$6:$G$93, Employee_KPI_Summary!$D$6:$D$93, B21) | F21: =SUMIFS(Employee_KPI_Summary!$H$6:$H$93, Employee_KPI_Summary!$D$6:$D$93, B21) | G21: =IF(D21>0, E21/D21, 0) | H21: =IF(SUMIFS(Employee_KPI_Summary!$K$6:$K$93, Employee_KPI_Summary!$D$6:$D$93, B21)>0, SUMIFS(Employee_KPI_Summary!$J$6:$J$93, Employee_KPI_Summary!$D$6:$D$93, B21)/SUMIFS(Employee_KPI_Summary!$K$6:$K$93, Employee_KPI_Summary!$D$6:$D$93, B21), 1.0) | I21: =IF(G21>=1.0, "Achieved", IF(G21>=0.75, "Good", IF(G21>=0.5, "Moderate", IF(G21>=0.25, "Low", "Critical")))) | J21: =G21+(1000-ROW())/1000000 | K21: =IF(C21>0, G21+ROW()/1000000, 9.99)
A22: =ROW() - 16 | B22: HR | C22: =COUNTIFS(Employee_KPI_Summary!$D$6:$D$93, B22, Employee_KPI_Summary!$F$6:$F$93, ">0") | D22: =SUMIFS(Employee_KPI_Summary!$F$6:$F$93, Employee_KPI_Summary!$D$6:$D$93, B22) | E22: =SUMIFS(Employee_KPI_Summary!$G$6:$G$93, Employee_KPI_Summary!$D$6:$D$93, B22) | F22: =SUMIFS(Employee_KPI_Summary!$H$6:$H$93, Employee_KPI_Summary!$D$6:$D$93, B22) | G22: =IF(D22>0, E22/D22, 0) | H22: =IF(SUMIFS(Employee_KPI_Summary!$K$6:$K$93, Employee_KPI_Summary!$D$6:$D$93, B22)>0, SUMIFS(Employee_KPI_Summary!$J$6:$J$93, Employee_KPI_Summary!$D$6:$D$93, B22)/SUMIFS(Employee_KPI_Summary!$K$6:$K$93, Employee_KPI_Summary!$D$6:$D$93, B22), 1.0) | I22: =IF(G22>=1.0, "Achieved", IF(G22>=0.75, "Good", IF(G22>=0.5, "Moderate", IF(G22>=0.25, "Low", "Critical")))) | J22: =G22+(1000-ROW())/1000000 | K22: =IF(C22>0, G22+ROW()/1000000, 9.99)
A23: =ROW() - 16 | B23: IT Support | C23: =COUNTIFS(Employee_KPI_Summary!$D$6:$D$93, B23, Employee_KPI_Summary!$F$6:$F$93, ">0") | D23: =SUMIFS(Employee_KPI_Summary!$F$6:$F$93, Employee_KPI_Summary!$D$6:$D$93, B23) | E23: =SUMIFS(Employee_KPI_Summary!$G$6:$G$93, Employee_KPI_Summary!$D$6:$D$93, B23) | F23: =SUMIFS(Employee_KPI_Summary!$H$6:$H$93, Employee_KPI_Summary!$D$6:$D$93, B23) | G23: =IF(D23>0, E23/D23, 0) | H23: =IF(SUMIFS(Employee_KPI_Summary!$K$6:$K$93, Employee_KPI_Summary!$D$6:$D$93, B23)>0, SUMIFS(Employee_KPI_Summary!$J$6:$J$93, Employee_KPI_Summary!$D$6:$D$93, B23)/SUMIFS(Employee_KPI_Summary!$K$6:$K$93, Employee_KPI_Summary!$D$6:$D$93, B23), 1.0) | I23: =IF(G23>=1.0, "Achieved", IF(G23>=0.75, "Good", IF(G23>=0.5, "Moderate", IF(G23>=0.25, "Low", "Critical")))) | J23: =G23+(1000-ROW())/1000000 | K23: =IF(C23>0, G23+ROW()/1000000, 9.99)
A24: =ROW() - 16 | B24: Maintenance | C24: =COUNTIFS(Employee_KPI_Summary!$D$6:$D$93, B24, Employee_KPI_Summary!$F$6:$F$93, ">0") | D24: =SUMIFS(Employee_KPI_Summary!$F$6:$F$93, Employee_KPI_Summary!$D$6:$D$93, B24) | E24: =SUMIFS(Employee_KPI_Summary!$G$6:$G$93, Employee_KPI_Summary!$D$6:$D$93, B24) | F24: =SUMIFS(Employee_KPI_Summary!$H$6:$H$93, Employee_KPI_Summary!$D$6:$D$93, B24) | G24: =IF(D24>0, E24/D24, 0) | H24: =IF(SUMIFS(Employee_KPI_Summary!$K$6:$K$93, Employee_KPI_Summary!$D$6:$D$93, B24)>0, SUMIFS(Employee_KPI_Summary!$J$6:$J$93, Employee_KPI_Summary!$D$6:$D$93, B24)/SUMIFS(Employee_KPI_Summary!$K$6:$K$93, Employee_KPI_Summary!$D$6:$D$93, B24), 1.0) | I24: =IF(G24>=1.0, "Achieved", IF(G24>=0.75, "Good", IF(G24>=0.5, "Moderate", IF(G24>=0.25, "Low", "Critical")))) | J24: =G24+(1000-ROW())/1000000 | K24: =IF(C24>0, G24+ROW()/1000000, 9.99)
A25: =ROW() - 16 | B25: Management | C25: =COUNTIFS(Employee_KPI_Summary!$D$6:$D$93, B25, Employee_KPI_Summary!$F$6:$F$93, ">0") | D25: =SUMIFS(Employee_KPI_Summary!$F$6:$F$93, Employee_KPI_Summary!$D$6:$D$93, B25) | E25: =SUMIFS(Employee_KPI_Summary!$G$6:$G$93, Employee_KPI_Summary!$D$6:$D$93, B25) | F25: =SUMIFS(Employee_KPI_Summary!$H$6:$H$93, Employee_KPI_Summary!$D$6:$D$93, B25) | G25: =IF(D25>0, E25/D25, 0) | H25: =IF(SUMIFS(Employee_KPI_Summary!$K$6:$K$93, Employee_KPI_Summary!$D$6:$D$93, B25)>0, SUMIFS(Employee_KPI_Summary!$J$6:$J$93, Employee_KPI_Summary!$D$6:$D$93, B25)/SUMIFS(Employee_KPI_Summary!$K$6:$K$93, Employee_KPI_Summary!$D$6:$D$93, B25), 1.0) | I25: =IF(G25>=1.0, "Achieved", IF(G25>=0.75, "Good", IF(G25>=0.5, "Moderate", IF(G25>=0.25, "Low", "Critical")))) | J25: =G25+(1000-ROW())/1000000 | K25: =IF(C25>0, G25+ROW()/1000000, 9.99)
A26: =ROW() - 16 | B26: Marketing | C26: =COUNTIFS(Employee_KPI_Summary!$D$6:$D$93, B26, Employee_KPI_Summary!$F$6:$F$93, ">0") | D26: =SUMIFS(Employee_KPI_Summary!$F$6:$F$93, Employee_KPI_Summary!$D$6:$D$93, B26) | E26: =SUMIFS(Employee_KPI_Summary!$G$6:$G$93, Employee_KPI_Summary!$D$6:$D$93, B26) | F26: =SUMIFS(Employee_KPI_Summary!$H$6:$H$93, Employee_KPI_Summary!$D$6:$D$93, B26) | G26: =IF(D26>0, E26/D26, 0) | H26: =IF(SUMIFS(Employee_KPI_Summary!$K$6:$K$93, Employee_KPI_Summary!$D$6:$D$93, B26)>0, SUMIFS(Employee_KPI_Summary!$J$6:$J$93, Employee_KPI_Summary!$D$6:$D$93, B26)/SUMIFS(Employee_KPI_Summary!$K$6:$K$93, Employee_KPI_Summary!$D$6:$D$93, B26), 1.0) | I26: =IF(G26>=1.0, "Achieved", IF(G26>=0.75, "Good", IF(G26>=0.5, "Moderate", IF(G26>=0.25, "Low", "Critical")))) | J26: =G26+(1000-ROW())/1000000 | K26: =IF(C26>0, G26+ROW()/1000000, 9.99)
A27: =ROW() - 16 | B27: NPD | C27: =COUNTIFS(Employee_KPI_Summary!$D$6:$D$93, B27, Employee_KPI_Summary!$F$6:$F$93, ">0") | D27: =SUMIFS(Employee_KPI_Summary!$F$6:$F$93, Employee_KPI_Summary!$D$6:$D$93, B27) | E27: =SUMIFS(Employee_KPI_Summary!$G$6:$G$93, Employee_KPI_Summary!$D$6:$D$93, B27) | F27: =SUMIFS(Employee_KPI_Summary!$H$6:$H$93, Employee_KPI_Summary!$D$6:$D$93, B27) | G27: =IF(D27>0, E27/D27, 0) | H27: =IF(SUMIFS(Employee_KPI_Summary!$K$6:$K$93, Employee_KPI_Summary!$D$6:$D$93, B27)>0, SUMIFS(Employee_KPI_Summary!$J$6:$J$93, Employee_KPI_Summary!$D$6:$D$93, B27)/SUMIFS(Employee_KPI_Summary!$K$6:$K$93, Employee_KPI_Summary!$D$6:$D$93, B27), 1.0) | I27: =IF(G27>=1.0, "Achieved", IF(G27>=0.75, "Good", IF(G27>=0.5, "Moderate", IF(G27>=0.25, "Low", "Critical")))) | J27: =G27+(1000-ROW())/1000000 | K27: =IF(C27>0, G27+ROW()/1000000, 9.99)
A28: =ROW() - 16 | B28: Operations | C28: =COUNTIFS(Employee_KPI_Summary!$D$6:$D$93, B28, Employee_KPI_Summary!$F$6:$F$93, ">0") | D28: =SUMIFS(Employee_KPI_Summary!$F$6:$F$93, Employee_KPI_Summary!$D$6:$D$93, B28) | E28: =SUMIFS(Employee_KPI_Summary!$G$6:$G$93, Employee_KPI_Summary!$D$6:$D$93, B28) | F28: =SUMIFS(Employee_KPI_Summary!$H$6:$H$93, Employee_KPI_Summary!$D$6:$D$93, B28) | G28: =IF(D28>0, E28/D28, 0) | H28: =IF(SUMIFS(Employee_KPI_Summary!$K$6:$K$93, Employee_KPI_Summary!$D$6:$D$93, B28)>0, SUMIFS(Employee_KPI_Summary!$J$6:$J$93, Employee_KPI_Summary!$D$6:$D$93, B28)/SUMIFS(Employee_KPI_Summary!$K$6:$K$93, Employee_KPI_Summary!$D$6:$D$93, B28), 1.0) | I28: =IF(G28>=1.0, "Achieved", IF(G28>=0.75, "Good", IF(G28>=0.5, "Moderate", IF(G28>=0.25, "Low", "Critical")))) | J28: =G28+(1000-ROW())/1000000 | K28: =IF(C28>0, G28+ROW()/1000000, 9.99)
... A33: =ROW() - 16 | B33: Stores | C33: =COUNTIFS(Employee_KPI_Summary!$D$6:$D$93, B33, Employee_KPI_Summary!$F$6:$F$93, ">0") | D33: =SUMIFS(Employee_KPI_Summary!$F$6:$F$93, Employee_KPI_Summary!$D$6:$D$93, B33) | E33: =SUMIFS(Employee_KPI_Summary!$G$6:$G$93, Employee_KPI_Summary!$D$6:$D$93, B33) | F33: =SUMIFS(Employee_KPI_Summary!$H$6:$H$93, Employee_KPI_Summary!$D$6:$D$93, B33) | G33: =IF(D33>0, E33/D33, 0) | H33: =IF(SUMIFS(Employee_KPI_Summary!$K$6:$K$93, Employee_KPI_Summary!$D$6:$D$93, B33)>0, SUMIFS(Employee_KPI_Summary!$J$6:$J$93, Employee_KPI_Summary!$D$6:$D$93, B33)/SUMIFS(Employee_KPI_Summary!$K$6:$K$93, Employee_KPI_Summary!$D$6:$D$93, B33), 1.0) | I33: =IF(G33>=1.0, "Achieved", IF(G33>=0.75, "Good", IF(G33>=0.5, "Moderate", IF(G33>=0.25, "Low", "Critical")))) | J33: =G33+(1000-ROW())/1000000 | K33: =IF(C33>0, G33+ROW()/1000000, 9.99)
B34: Total | C34: =SUM(C17:C33) | D34: =SUM(D17:D33) | E34: =SUM(E17:E33) | F34: =SUM(F17:F33) | G34: =IF(D34>0, E34/D34, 0) | H34: =IF(SUM(Employee_KPI_Summary!$K$6:$K$93)>0, SUM(Employee_KPI_Summary!$J$6:$J$93)/SUM(Employee_KPI_Summary!$K$6:$K$93), 1.0) | I34: =IF(G34>=1.0, "Achieved", IF(G34>=0.75, "Good", IF(G34>=0.5, "Moderate", IF(G34>=0.25, "Low", "Critical"))))
A37: Top Performing Departments | G37: Departments Requiring Attention
A38: Rank | B38: Department | C38: Achievement % | D38: Actual Hours | E38: Attendance % | G38: Department | H38: Remaining Hours | I38: Compliance % | J38: Risk Indicator
A39: 1 | B39: =INDEX($B$17:$B$33, MATCH(LARGE($J$17:$J$33, A39), $J$17:$J$33, 0)) | C39: =INDEX($G$17:$G$33, MATCH(LARGE($J$17:$J$33, A39), $J$17:$J$33, 0)) | D39: =INDEX($E$17:$E$33, MATCH(LARGE($J$17:$J$33, A39), $J$17:$J$33, 0)) | E39: =INDEX($H$17:$H$33, MATCH(LARGE($J$17:$J$33, A39), $J$17:$J$33, 0)) | G39: =INDEX($B$17:$B$33, MATCH(SMALL($K$17:$K$33, 1), $K$17:$K$33, 0)) | H39: =INDEX($F$17:$F$33, MATCH(SMALL($K$17:$K$33, 1), $K$17:$K$33, 0)) | I39: =INDEX($G$17:$G$33, MATCH(SMALL($K$17:$K$33, 1), $K$17:$K$33, 0)) | J39: =IF(I39<0.5, "🔴 Critical Risk", IF(I39<0.75, "🟡 Moderate Risk", "🟢 Low Risk"))
A40: 2 | B40: =INDEX($B$17:$B$33, MATCH(LARGE($J$17:$J$33, A40), $J$17:$J$33, 0)) | C40: =INDEX($G$17:$G$33, MATCH(LARGE($J$17:$J$33, A40), $J$17:$J$33, 0)) | D40: =INDEX($E$17:$E$33, MATCH(LARGE($J$17:$J$33, A40), $J$17:$J$33, 0)) | E40: =INDEX($H$17:$H$33, MATCH(LARGE($J$17:$J$33, A40), $J$17:$J$33, 0)) | G40: =INDEX($B$17:$B$33, MATCH(SMALL($K$17:$K$33, 2), $K$17:$K$33, 0)) | H40: =INDEX($F$17:$F$33, MATCH(SMALL($K$17:$K$33, 2), $K$17:$K$33, 0)) | I40: =INDEX($G$17:$G$33, MATCH(SMALL($K$17:$K$33, 2), $K$17:$K$33, 0)) | J40: =IF(I40<0.5, "🔴 Critical Risk", IF(I40<0.75, "🟡 Moderate Risk", "🟢 Low Risk"))
A41: 3 | B41: =INDEX($B$17:$B$33, MATCH(LARGE($J$17:$J$33, A41), $J$17:$J$33, 0)) | C41: =INDEX($G$17:$G$33, MATCH(LARGE($J$17:$J$33, A41), $J$17:$J$33, 0)) | D41: =INDEX($E$17:$E$33, MATCH(LARGE($J$17:$J$33, A41), $J$17:$J$33, 0)) | E41: =INDEX($H$17:$H$33, MATCH(LARGE($J$17:$J$33, A41), $J$17:$J$33, 0)) | G41: =INDEX($B$17:$B$33, MATCH(SMALL($K$17:$K$33, 3), $K$17:$K$33, 0)) | H41: =INDEX($F$17:$F$33, MATCH(SMALL($K$17:$K$33, 3), $K$17:$K$33, 0)) | I41: =INDEX($G$17:$G$33, MATCH(SMALL($K$17:$K$33, 3), $K$17:$K$33, 0)) | J41: =IF(I41<0.5, "🔴 Critical Risk", IF(I41<0.75, "🟡 Moderate Risk", "🟢 Low Risk"))
A42: 4 | B42: =INDEX($B$17:$B$33, MATCH(LARGE($J$17:$J$33, A42), $J$17:$J$33, 0)) | C42: =INDEX($G$17:$G$33, MATCH(LARGE($J$17:$J$33, A42), $J$17:$J$33, 0)) | D42: =INDEX($E$17:$E$33, MATCH(LARGE($J$17:$J$33, A42), $J$17:$J$33, 0)) | E42: =INDEX($H$17:$H$33, MATCH(LARGE($J$17:$J$33, A42), $J$17:$J$33, 0)) | G42: =INDEX($B$17:$B$33, MATCH(SMALL($K$17:$K$33, 4), $K$17:$K$33, 0)) | H42: =INDEX($F$17:$F$33, MATCH(SMALL($K$17:$K$33, 4), $K$17:$K$33, 0)) | I42: =INDEX($G$17:$G$33, MATCH(SMALL($K$17:$K$33, 4), $K$17:$K$33, 0)) | J42: =IF(I42<0.5, "🔴 Critical Risk", IF(I42<0.75, "🟡 Moderate Risk", "🟢 Low Risk"))
A43: 5 | B43: =INDEX($B$17:$B$33, MATCH(LARGE($J$17:$J$33, A43), $J$17:$J$33, 0)) | C43: =INDEX($G$17:$G$33, MATCH(LARGE($J$17:$J$33, A43), $J$17:$J$33, 0)) | D43: =INDEX($E$17:$E$33, MATCH(LARGE($J$17:$J$33, A43), $J$17:$J$33, 0)) | E43: =INDEX($H$17:$H$33, MATCH(LARGE($J$17:$J$33, A43), $J$17:$J$33, 0)) | G43: =INDEX($B$17:$B$33, MATCH(SMALL($K$17:$K$33, 5), $K$17:$K$33, 0)) | H43: =INDEX($F$17:$F$33, MATCH(SMALL($K$17:$K$33, 5), $K$17:$K$33, 0)) | I43: =INDEX($G$17:$G$33, MATCH(SMALL($K$17:$K$33, 5), $K$17:$K$33, 0)) | J43: =IF(I43<0.5, "🔴 Critical Risk", IF(I43<0.75, "🟡 Moderate Risk", "🟢 Low Risk"))
A46: Monthly Learning Trends (FY) | G46: Executive KPI Insights
A47: Month | B47: Target Hours | C47: Actual Hours | D47: Achievement %
A48: April | B48: =$A$11 * 1.33 | C48: =SUMIFS(Raw_Attendance_Data!$S$2:$S$2, Raw_Attendance_Data!$I$2:$I$2, A48, Raw_Attendance_Data!$A$2:$A$2, 1) | D48: =IF(B48>0, C48/B48, 0) | G48: ="• " & INDEX(B17:B33, MATCH(MAX(E17:E33), E17:E33, 0)) & " contributed the highest learning hours (" & TEXT(MAX(E17:E33), "#,##0") & " hours)."
A49: May | B49: =$A$11 * 1.33 | C49: =SUMIFS(Raw_Attendance_Data!$S$2:$S$2, Raw_Attendance_Data!$I$2:$I$2, A49, Raw_Attendance_Data!$A$2:$A$2, 1) | D49: =IF(B49>0, C49/B49, 0) | G49: ="• " & INDEX(B17:B33, MATCH(MIN(K17:K33), K17:K33, 0)) & " is " & TEXT(MAX(0, 1-MIN(K17:K33)), "0%") & " below annual learning target."
A50: June | B50: =$A$11 * 1.33 | C50: =SUMIFS(Raw_Attendance_Data!$S$2:$S$2, Raw_Attendance_Data!$I$2:$I$2, A50, Raw_Attendance_Data!$A$2:$A$2, 1) | D50: =IF(B50>0, C50/B50, 0) | G50: ="• " & INDEX(B17:B33, MATCH(MAX(G17:G33), G17:G33, 0)) & " achieved " & TEXT(MAX(G17:G33), "0.0%") & " learning compliance."
A51: July | B51: =$A$11 * 1.33 | C51: =SUMIFS(Raw_Attendance_Data!$S$2:$S$2, Raw_Attendance_Data!$I$2:$I$2, A51, Raw_Attendance_Data!$A$2:$A$2, 1) | D51: =IF(B51>0, C51/B51, 0) | G51: ="• Organization-wide learning compliance stands at " & TEXT(A13, "0.0%") & "."
A52: August | B52: =$A$11 * 1.33 | C52: =SUMIFS(Raw_Attendance_Data!$S$2:$S$2, Raw_Attendance_Data!$I$2:$I$2, A52, Raw_Attendance_Data!$A$2:$A$2, 1) | D52: =IF(B52>0, C52/B52, 0)
A53: September | B53: =$A$11 * 1.33 | C53: =SUMIFS(Raw_Attendance_Data!$S$2:$S$2, Raw_Attendance_Data!$I$2:$I$2, A53, Raw_Attendance_Data!$A$2:$A$2, 1) | D53: =IF(B53>0, C53/B53, 0)
...

Sheet Raw_Attendance_Data
A1: Matches_Filter | B1: Employee Code | C1: Employee Name | D1: Department | E1: Manager | F1: Training Date | G1: Financial Year | H1: Quarter | I1: Month Name | J1: Training Title | K1: Training Category | L1: Training Type | M1: Attendance Status | N1: Actual Hours | O1: Max Hours | P1: Is_Unique_Training | Q1: Is_Attended_Present | R1: Is_Completed | S1: Actual Hours Credit

Sheet Employee_KPI_Summary
A1: Detailed Employee KPI Metrics & Compliance Status
A2: Do not edit this sheet directly. It contains formulas linking Employee metrics to the Dashboard filters.
A6: 1 | B6: 001 | C6: Sagar Ramesh | D6: QA | E6: Srinivasan Beeman | F6: =IF(OR('Department KPI Analytics'!$G$6="All", D6='Department KPI Analytics'!$G$6), 16, 0) | G6: =SUMIFS(Raw_Attendance_Data!$S$2:$S$2, Raw_Attendance_Data!$B$2:$B$2, B6, Raw_Attendance_Data!$A$2:$A$2, 1) | H6: =MAX(F6-G6, 0) | I6: =IF(F6>0, G6/F6, 0) | J6: =COUNTIFS(Raw_Attendance_Data!$B$2:$B$2, B6, Raw_Attendance_Data!$A$2:$A$2, 1, Raw_Attendance_Data!$Q$2:$Q$2, 1) | K6: =COUNTIFS(Raw_Attendance_Data!$B$2:$B$2, B6, Raw_Attendance_Data!$A$2:$A$2, 1) | L6: =IF(K6>0, J6/K6, 1.0)
A7: 2 | B7: 003 | C7: Megha Lakshmi Murugamani | D7: CRM | E7: Prakash Padukhone Muthiah | F7: =IF(OR('Department KPI Analytics'!$G$6="All", D7='Department KPI Analytics'!$G$6), 16, 0) | G7: =SUMIFS(Raw_Attendance_Data!$S$2:$S$2, Raw_Attendance_Data!$B$2:$B$2, B7, Raw_Attendance_Data!$A$2:$A$2, 1) | H7: =MAX(F7-G7, 0) | I7: =IF(F7>0, G7/F7, 0) | J7: =COUNTIFS(Raw_Attendance_Data!$B$2:$B$2, B7, Raw_Attendance_Data!$A$2:$A$2, 1, Raw_Attendance_Data!$Q$2:$Q$2, 1) | K7: =COUNTIFS(Raw_Attendance_Data!$B$2:$B$2, B7, Raw_Attendance_Data!$A$2:$A$2, 1) | L7: =IF(K7>0, J7/K7, 1.0)
A8: 3 | B8: 005 | C8: Arunkumar Selvaraj | D8: RFQ | E8: R Rathina Kumar | F8: =IF(OR('Department KPI Analytics'!$G$6="All", D8='Department KPI Analytics'!$G$6), 16, 0) | G8: =SUMIFS(Raw_Attendance_Data!$S$2:$S$2, Raw_Attendance_Data!$B$2:$B$2, B8, Raw_Attendance_Data!$A$2:$A$2, 1) | H8: =MAX(F8-G8, 0) | I8: =IF(F8>0, G8/F8, 0) | J8: =COUNTIFS(Raw_Attendance_Data!$B$2:$B$2, B8, Raw_Attendance_Data!$A$2:$A$2, 1, Raw_Attendance_Data!$Q$2:$Q$2, 1) | K8: =COUNTIFS(Raw_Attendance_Data!$B$2:$B$2, B8, Raw_Attendance_Data!$A$2:$A$2, 1) | L8: =IF(K8>0, J8/K8, 1.0)
A9: 4 | B9: 006 | C9: Nalini Vasudevan | D9: Stores | E9: Sakthivel Muthu | F9: =IF(OR('Department KPI Analytics'!$G$6="All", D9='Department KPI Analytics'!$G$6), 16, 0) | G9: =SUMIFS(Raw_Attendance_Data!$S$2:$S$2, Raw_Attendance_Data!$B$2:$B$2, B9, Raw_Attendance_Data!$A$2:$A$2, 1) | H9: =MAX(F9-G9, 0) | I9: =IF(F9>0, G9/F9, 0) | J9: =COUNTIFS(Raw_Attendance_Data!$B$2:$B$2, B9, Raw_Attendance_Data!$A$2:$A$2, 1, Raw_Attendance_Data!$Q$2:$Q$2, 1) | K9: =COUNTIFS(Raw_Attendance_Data!$B$2:$B$2, B9, Raw_Attendance_Data!$A$2:$A$2, 1) | L9: =IF(K9>0, J9/K9, 1.0)
A10: 5 | B10: 007 | C10: Naveenkumar M | D10: NPD | E10: Prakash Padukhone Muthiah | F10: =IF(OR('Department KPI Analytics'!$G$6="All", D10='Department KPI Analytics'!$G$6), 16, 0) | G10: =SUMIFS(Raw_Attendance_Data!$S$2:$S$2, Raw_Attendance_Data!$B$2:$B$2, B10, Raw_Attendance_Data!$A$2:$A$2, 1) | H10: =MAX(F10-G10, 0) | I10: =IF(F10>0, G10/F10, 0) | J10: =COUNTIFS(Raw_Attendance_Data!$B$2:$B$2, B10, Raw_Attendance_Data!$A$2:$A$2, 1, Raw_Attendance_Data!$Q$2:$Q$2, 1) | K10: =COUNTIFS(Raw_Attendance_Data!$B$2:$B$2, B10, Raw_Attendance_Data!$A$2:$A$2, 1) | L10: =IF(K10>0, J10/K10, 1.0)
A11: 6 | B11: 008 | C11: Nethaji Raja | D11: QA | E11: R Rathina Kumar | F11: =IF(OR('Department KPI Analytics'!$G$6="All", D11='Department KPI Analytics'!$G$6), 16, 0) | G11: =SUMIFS(Raw_Attendance_Data!$S$2:$S$2, Raw_Attendance_Data!$B$2:$B$2, B11, Raw_Attendance_Data!$A$2:$A$2, 1) | H11: =MAX(F11-G11, 0) | I11: =IF(F11>0, G11/F11, 0) | J11: =COUNTIFS(Raw_Attendance_Data!$B$2:$B$2, B11, Raw_Attendance_Data!$A$2:$A$2, 1, Raw_Attendance_Data!$Q$2:$Q$2, 1) | K11: =COUNTIFS(Raw_Attendance_Data!$B$2:$B$2, B11, Raw_Attendance_Data!$A$2:$A$2, 1) | L11: =IF(K11>0, J11/K11, 1.0)
A12: 7 | B12: 011 | C12: Mariyaruban Mariyakilaimans | D12: Accounts | E12: Arunachalam Palaniappan | F12: =IF(OR('Department KPI Analytics'!$G$6="All", D12='Department KPI Analytics'!$G$6), 16, 0) | G12: =SUMIFS(Raw_Attendance_Data!$S$2:$S$2, Raw_Attendance_Data!$B$2:$B$2, B12, Raw_Attendance_Data!$A$2:$A$2, 1) | H12: =MAX(F12-G12, 0) | I12: =IF(F12>0, G12/F12, 0) | J12: =COUNTIFS(Raw_Attendance_Data!$B$2:$B$2, B12, Raw_Attendance_Data!$A$2:$A$2, 1, Raw_Attendance_Data!$Q$2:$Q$2, 1) | K12: =COUNTIFS(Raw_Attendance_Data!$B$2:$B$2, B12, Raw_Attendance_Data!$A$2:$A$2, 1) | L12: =IF(K12>0, J12/K12, 1.0)
A13: 8 | B13: 013 | C13: Govindammal . | D13: QA | E13: Srinivasan Beeman | F13: =IF(OR('Department KPI Analytics'!$G$6="All", D13='Department KPI Analytics'!$G$6), 16, 0) | G13: =SUMIFS(Raw_Attendance_Data!$S$2:$S$2, Raw_Attendance_Data!$B$2:$B$2, B13, Raw_Attendance_Data!$A$2:$A$2, 1) | H13: =MAX(F13-G13, 0) | I13: =IF(F13>0, G13/F13, 0) | J13: =COUNTIFS(Raw_Attendance_Data!$B$2:$B$2, B13, Raw_Attendance_Data!$A$2:$A$2, 1, Raw_Attendance_Data!$Q$2:$Q$2, 1) | K13: =COUNTIFS(Raw_Attendance_Data!$B$2:$B$2, B13, Raw_Attendance_Data!$A$2:$A$2, 1) | L13: =IF(K13>0, J13/K13, 1.0)
A14: 9 | B14: 015 | C14: Sangeetha Murugan | D14: QA | E14: Srinivasan Beeman | F14: =IF(OR('Department KPI Analytics'!$G$6="All", D14='Department KPI Analytics'!$G$6), 16, 0) | G14: =SUMIFS(Raw_Attendance_Data!$S$2:$S$2, Raw_Attendance_Data!$B$2:$B$2, B14, Raw_Attendance_Data!$A$2:$A$2, 1) | H14: =MAX(F14-G14, 0) | I14: =IF(F14>0, G14/F14, 0) | J14: =COUNTIFS(Raw_Attendance_Data!$B$2:$B$2, B14, Raw_Attendance_Data!$A$2:$A$2, 1, Raw_Attendance_Data!$Q$2:$Q$2, 1) | K14: =COUNTIFS(Raw_Attendance_Data!$B$2:$B$2, B14, Raw_Attendance_Data!$A$2:$A$2, 1) | L14: =IF(K14>0, J14/K14, 1.0)
A15: 10 | B15: 016 | C15: Gunasekaran Kaveri Setty | D15: QA | E15: Srinivasan Beeman | F15: =IF(OR('Department KPI Analytics'!$G$6="All", D15='Department KPI Analytics'!$G$6), 16, 0) | G15: =SUMIFS(Raw_Attendance_Data!$S$2:$S$2, Raw_Attendance_Data!$B$2:$B$2, B15, Raw_Attendance_Data!$A$2:$A$2, 1) | H15: =MAX(F15-G15, 0) | I15: =IF(F15>0, G15/F15, 0) | J15: =COUNTIFS(Raw_Attendance_Data!$B$2:$B$2, B15, Raw_Attendance_Data!$A$2:$A$2, 1, Raw_Attendance_Data!$Q$2:$Q$2, 1) | K15: =COUNTIFS(Raw_Attendance_Data!$B$2:$B$2, B15, Raw_Attendance_Data!$A$2:$A$2, 1) | L15: =IF(K15>0, J15/K15, 1.0)
A16: 11 | B16: 017 | C16: Saravana Hanumanthappa | D16: IT Support | E16: Manasa R | F16: =IF(OR('Department KPI Analytics'!$G$6="All", D16='Department KPI Analytics'!$G$6), 16, 0) | G16: =SUMIFS(Raw_Attendance_Data!$S$2:$S$2, Raw_Attendance_Data!$B$2:$B$2, B16, Raw_Attendance_Data!$A$2:$A$2, 1) | H16: =MAX(F16-G16, 0) | I16: =IF(F16>0, G16/F16, 0) | J16: =COUNTIFS(Raw_Attendance_Data!$B$2:$B$2, B16, Raw_Attendance_Data!$A$2:$A$2, 1, Raw_Attendance_Data!$Q$2:$Q$2, 1) | K16: =COUNTIFS(Raw_Attendance_Data!$B$2:$B$2, B16, Raw_Attendance_Data!$A$2:$A$2, 1) | L16: =IF(K16>0, J16/K16, 1.0)
A17: 12 | B17: 018 | C17: Perumal Govindharaj | D17: QA | E17: Srinivasan Beeman | F17: =IF(OR('Department KPI Analytics'!$G$6="All", D17='Department KPI Analytics'!$G$6), 16, 0) | G17: =SUMIFS(Raw_Attendance_Data!$S$2:$S$2, Raw_Attendance_Data!$B$2:$B$2, B17, Raw_Attendance_Data!$A$2:$A$2, 1) | H17: =MAX(F17-G17, 0) | I17: =IF(F17>0, G17/F17, 0) | J17: =COUNTIFS(Raw_Attendance_Data!$B$2:$B$2, B17, Raw_Attendance_Data!$A$2:$A$2, 1, Raw_Attendance_Data!$Q$2:$Q$2, 1) | K17: =COUNTIFS(Raw_Attendance_Data!$B$2:$B$2, B17, Raw_Attendance_Data!$A$2:$A$2, 1) | L17: =IF(K17>0, J17/K17, 1.0)
... A90: 85 | B90: DUMMY-PRAKASH | C90: Prakash Padukhone Muthiah | D90: Operations | E90: Nitin R Patel | F90: =IF(OR('Department KPI Analytics'!$G$6="All", D90='Department KPI Analytics'!$G$6), 16, 0) | G90: =SUMIFS(Raw_Attendance_Data!$S$2:$S$2, Raw_Attendance_Data!$B$2:$B$2, B90, Raw_Attendance_Data!$A$2:$A$2, 1) | H90: =MAX(F90-G90, 0) | I90: =IF(F90>0, G90/F90, 0) | J90: =COUNTIFS(Raw_Attendance_Data!$B$2:$B$2, B90, Raw_Attendance_Data!$A$2:$A$2, 1, Raw_Attendance_Data!$Q$2:$Q$2, 1) | K90: =COUNTIFS(Raw_Attendance_Data!$B$2:$B$2, B90, Raw_Attendance_Data!$A$2:$A$2, 1) | L90: =IF(K90>0, J90/K90, 1.0)
A91: 86 | B91: MGR001 | C91: Team Manager | D91: Management | F91: =IF(OR('Department KPI Analytics'!$G$6="All", D91='Department KPI Analytics'!$G$6), 16, 0) | G91: =SUMIFS(Raw_Attendance_Data!$S$2:$S$2, Raw_Attendance_Data!$B$2:$B$2, B91, Raw_Attendance_Data!$A$2:$A$2, 1) | H91: =MAX(F91-G91, 0) | I91: =IF(F91>0, G91/F91, 0) | J91: =COUNTIFS(Raw_Attendance_Data!$B$2:$B$2, B91, Raw_Attendance_Data!$A$2:$A$2, 1, Raw_Attendance_Data!$Q$2:$Q$2, 1) | K91: =COUNTIFS(Raw_Attendance_Data!$B$2:$B$2, B91, Raw_Attendance_Data!$A$2:$A$2, 1) | L91: =IF(K91>0, J91/K91, 1.0)
A92: 87 | B92: SGS-KET | C92: Ketan BC | D92: Management | E92: Team Manager | F92: =IF(OR('Department KPI Analytics'!$G$6="All", D92='Department KPI Analytics'!$G$6), 16, 0) | G92: =SUMIFS(Raw_Attendance_Data!$S$2:$S$2, Raw_Attendance_Data!$B$2:$B$2, B92, Raw_Attendance_Data!$A$2:$A$2, 1) | H92: =MAX(F92-G92, 0) | I92: =IF(F92>0, G92/F92, 0) | J92: =COUNTIFS(Raw_Attendance_Data!$B$2:$B$2, B92, Raw_Attendance_Data!$A$2:$A$2, 1, Raw_Attendance_Data!$Q$2:$Q$2, 1) | K92: =COUNTIFS(Raw_Attendance_Data!$B$2:$B$2, B92, Raw_Attendance_Data!$A$2:$A$2, 1) | L92: =IF(K92>0, J92/K92, 1.0)
A93: 88 | B93: SGS-NIT | C93: Nitin R Patel | D93: Management | E93: Team Manager | F93: =IF(OR('Department KPI Analytics'!$G$6="All", D93='Department KPI Analytics'!$G$6), 16, 0) | G93: =SUMIFS(Raw_Attendance_Data!$S$2:$S$2, Raw_Attendance_Data!$B$2:$B$2, B93, Raw_Attendance_Data!$A$2:$A$2, 1) | H93: =MAX(F93-G93, 0) | I93: =IF(F93>0, G93/F93, 0) | J93: =COUNTIFS(Raw_Attendance_Data!$B$2:$B$2, B93, Raw_Attendance_Data!$A$2:$A$2, 1, Raw_Attendance_Data!$Q$2:$Q$2, 1) | K93: =COUNTIFS(Raw_Attendance_Data!$B$2:$B$2, B93, Raw_Attendance_Data!$A$2:$A$2, 1) | L93: =IF(K93>0, J93/K93, 1.0)

Sheet Filter_Lists
A1: Financial Years | B1: Quarters | C1: Months | D1: Departments | E1: Categories | F1: Managers | G1: Training Types
A2: All | B2: All | C2: All | D2: All | E2: All | F2: All | G2: All
A3: 2025-2026 | B3: Q1 | C3: April | D3: Accounts | E3: Compliance & Safety | F3: Anil Kumar Joshi | G3: INTERNAL
B4: Q2 | C4: May | D4: Casting | E4: Finance & Accounting | F4: Arunachalam Palaniappan | G4: EXTERNAL
B5: Q3 | C5: June | D5: Commercial | E5: HR & People | F5: Harsora Rajan Bakulbhai | G5: ONLINE
B6: Q4 | C6: July | D6: CRM | E6: Leadership & Management | F6: Ketan BC | G6: WORKSHOP
C7: August | D7: Driver | E7: Product & Domain | F7: Manasa R | G7: CERTIFICATION
C8: September | D8: HR | E8: Sales & Customer Service | F8: Naveenkumar M
C9: October | D9: IT Support | E9: Soft Skills | F9: Nethaji Raja
C10: November | D10: Maintenance | E10: Technical Skills | F10: Nitin R Patel
C11: December | D11: Management | F11: Prakash Padukhone Muthiah
C12: January | D12: Marketing | F12: R Rathina Kumar
C13: February | D13: NPD | F13: Rajeshwari Ganeshkumar
C14: March | D14: Operations | F14: Sakthivel Muthu
D15: Purchase Castings | F15: Sakthivel Muthu
D16: QA | F16: Srinivasan Beeman
D17: RFQ | F17: Sundaravel S
D18: Sourcing | F18: Swetha Swetha
D19: Stores | F19: Team Manager
F20: Vinit Praful Karia
