Workbook

Sheet Department KPI Analytics
A1: ORGANIZATION LEARNING & KPI ANALYTICS DASHBOARD
A2: Executive Business Intelligence & Learning Compliance Report
A4: Interactive Filters (Select values to dynamically update the dashboard)
B5: Financial Year | D5: Quarter | E5: Month | G5: Department
B6: All | D6: All | E6: All | G6: All
B7: Training Category | E7: Manager | H7: Training Type
B8: All | E8: All | H8: All
A10: TOTAL EMPLOYEES | C10: TOTAL TARGET HOURS | E10: TOTAL ACTUAL HOURS | G10: TOTAL REMAINING HOURS | I10: OVERALL ACHIEVEMENT %
A11: =COUNTIFS(Employee_KPI_Summary!$F$6:$F$93, ">0") | C11: =SUM(Employee_KPI_Summary!$F$6:$F$93) | E11: =SUM(Employee_KPI_Summary!$G$6:$G$93) | G11: =SUM(Employee_KPI_Summary!$H$6:$H$93) | I11: =IF(C11>0, E11/C11, 0)
A12: LEARNING COMPLIANCE % | C12: TRAININGS CONDUCTED | E12: TOTAL ATTENDANCE % | G12: TOP PERFORMING DEPT | I12: LOWEST PERFORMING DEPT
A13: =IF(COUNTIFS(Employee_KPI_Summary!$F$6:$F$93, ">0")>0, COUNTIFS(Employee_KPI_Summary!$F$6:$F$93, ">0", Employee_KPI_Summary!$I$6:$I$93, ">=1.0")/COUNTIFS(Employee_KPI_Summary!$F$6:$F$93, ">0"), 1.0) | C13: =SUM(Raw_Attendance_Data!$P$2:$P$3) | E13: =IF(SUM(Employee_KPI_Summary!$K$6:$K$93)>0, SUM(Employee_KPI_Summary!$J$6:$J$93)/SUM(Employee_KPI_Summary!$K$6:$K$93), 1.0) | G13: =INDEX(B17:B33, MATCH(MAX(G17:G33), G17:G33, 0)) | I13: =INDEX(B17:B33, MATCH(MIN(K17:K33), K17:K33, 0))
A15: DEPARTMENT CONTRIBUTION & KPI SUMMARY
A16: S.No | B16: Department | C16: Employees | D16: Target Hours | E16: Actual Hours | F16: Remaining Hours | G16: Achievement % | H16: Attendance % | I16: KPI Status | J16: Rank Score | K16: Filtered Achievement
A17: =ROW() - 16 | B17: Accounts | C17: =COUNTIFS(Employee_KPI_Summary!$D$6:$D$93, B17, Employee_KPI_Summary!$F$6:$F$93, ">0") | D17: =SUMIFS(Employee_KPI_Summary!$F$6:$F$93, Employee_KPI_Summary!$D$6:$D$93, B17) | E17: =SUMIFS(Employee_KPI_Summary!$G$6:$G$93, Employee_KPI_Summary!$D$6:$D$93, B17) | F17: =SUMIFS(Employee_KPI_Summary!$H$6:$H$93, Employee_KPI_Summary!$D$6:$D$93, B17) | G17: =IF(D17>0, E17/D17, 0) | H17: =IF(SUMIFS(Employee_KPI_Summary!$K$6:$K$93, Employee_KPI_Summary!$D$6:$D$93, B17)>0, SUMIFS(Employee_KPI_Summary!$J$6:$J$93, Employee_KPI_Summary!$D$6:$D$93, B17)/SUMIFS(Employee_KPI_Summary!$K$6:$K$93, Employee_KPI_Summary!$D$6:$D$93, B17), 1.0) | I17: =IF(G17>=1.0, "Achieved", IF(G17>=0.75, "Good", IF(G17>=0.5, "Moderate", IF(G17>=0.25, "Low", "Critical")))) | J17: =G17+(1000-ROW())/1000000 | K17: =IF(C17>0, G17+ROW()/1000000, 9.99)
A18: =ROW() - 16 | B18: Casting | C18: =COUNTIFS(Employee_KPI_Summary!$D$6:$D$93, B18, Employee_KPI_Summary!$F$6:$F$93, ">0") | D18: =SUMIFS(Employee_KPI_Summary!$F$6:$F$93, Employee_KPI_Summary!$D$6:$D$93, B18) | E18: =SUMIFS(Employee_KPI_Summary!$G$6:$G$93, Employee_KPI_Summary!$D$6:$D$93, B18) | F18: =SUMIFS(Employee_KPI_Summary!$H$6:$H$93, Employee_KPI_Summary!$D$6:$D$93, B18) | G18: =IF(D18>0, E18/D18, 0) | H18: =IF(SUMIFS(Employee_KPI_Summary!$K$6:$K$93, Employee_KPI_Summary!$D$6:$D$93, B18)>0, SUMIFS(Employee_KPI_Summary!$J$6:$J$93, Employee_KPI_Summary!$D$6:$D$93, B18)/SUMIFS(Employee_KPI_Summary!$K$6:$K$93, Employee_KPI_Summary!$D$6:$D$93, B18), 1.0) | I18: =IF(G18>=1.0, "Achieved", IF(G18>=0.75, "Good", IF(G18>=0.5, "Moderate", IF(G18>=0.25, "Low", "Critical")))) | J18: =G18+(1000-ROW())/1000000 | K18: =IF(C18>0, G18+ROW()/1000000, 9.99)
A19: =ROW() - 16 | B19: Commercial | C19: =COUNTIFS(Employee_KPI_Summary!$D$6:$D$93, B19, Employee_KPI_Summary!$F$6:$F$93, ">0") | D19: =SUMIFS(Employee_KPI_Summary!$F$6:$F$93, Employee_KPI_Summary!$D$6:$D$93, B19) | E19: =SUMIFS(Employee_KPI_Summary!$G$6:$G$93, Employee_KPI_Summary!$D$6:$D$93, B19) | F19: =SUMIFS(Employee_KPI_Summary!$H$6:$H$93, Employee_KPI_Summary!$D$6:$D$93, B19) | G19: =IF(D19>0, E19/D19, 0) | H19: =IF(SUMIFS(Employee_KPI_Summary!$K$6:$K$93, Employee_KPI_Summary!$D$6:$D$93, B19)>0, SUMIFS(Employee_KPI_Summary!$J$6:$J$93, Employee_KPI_Summary!$D$6:$D$93, B19)/SUMIFS(Employee_KPI_Summary!$K$6:$K$93, Employee_KPI_Summary!$D$6:$D$93, B19), 1.0) | I19: =IF(G19>=1.0, "Achieved", IF(G19>=0.75, "Good", IF(G19>=0.5, "Moderate", IF(G19>=0.25, "Low", "Critical")))) | J19: =G19+(1000-ROW())/1000000 | K19: =IF(C19>0, G19+ROW()/1000000, 9.99)
A20: =ROW() - 16 | B20: CRM | C20: =COUNTIFS(Employee_KPI_Summary!$D$6:$D$93, B20, Employee_KPI_Summary!$F$6:$F$93, ">0") | D20: =SUMIFS(Employee_KPI_Summary!$F$6:$F$93, Employee_KPI_Summary!$D$6:$D$93, B20) | E20: =SUMIFS(Employee_KPI_Summary!$G$6:$G$93, Employee_KPI_Summary!$D$6:$D$93, B20) | F20: =SUMIFS(Employee_KPI_Summary!$H$6:$H$93, Employee_KPI_Summary!$D$6:$D$93, B20) | G20: =IF(D20>0, E20/D20, 0) | H20: =IF(SUMIFS(Employee_KPI_Summary!$K$6:$K$93, Employee_KPI_Summary!$D$6:$D$93, B20)>0, SUMIFS(Employee_KPI_Summary!$J$6:$J$93, Employee_KPI_Summary!$D$6:$D$93, B20)/SUMIFS(Employee_KPI_Summary!$K$6:$K$93, Employee_KPI_Summary!$D$6:$D$93, B20), 1.0) | I20: =IF(G20>=1.0, "Achieved", IF(G20>=0.75, "Good", IF(G20>=0.5, "Moderate", IF(G20>=0.25, "Low", "Critical")))) | J20: =G20+(1000-ROW())/1000000 | K20: =IF(C20>0, G20+ROW()/1000000, 9.99)
A21: =ROW() - 16 | B21: Driver | C21: =COUNTIFS(Employee_KPI_Summary!$D$6:$D$93, B21, Employee_KPI_Summary!$F$6:$F$93, ">0") | D21: =SUMIFS(Employee_KPI_Summary!$F$6:$F$93, Employee_KPI_Summary!$D$6:$D$93, B21) | E21: =SUMIFS(Employee_KPI_Summary!$G$6:$G$93, Employee_KPI_Summary!$D$6:$D$93, B21) | F21: =SUMIFS(Employee_KPI_Summary!$H$6:$H$93, Employee_KPI_Summary!$D$6:$D$93, B21) | G21: =IF(D21>0, E21/D21, 0) | H21: =IF(SUMIFS(Employee_KPI_Summary!$K$6:$K$93, Employee_KPI_Summary!$D$6:$D$93, B21)>0, SUMIFS(Employee_KPI_Summary!$J$6:$J$93, Employee_KPI_Summary!$D$6:$D$93, B21)/SUMIFS(Employee_KPI_Summary!$K$6:$K$93, Employee_KPI_Summary!$D$6:$D$93, B21), 1.0) | I21: =IF(G21>=1.0, "Achieved", IF(G21>=0.75, "Good", IF(G21>=0.5, "Moderate", IF(G21>=0.25, "Low", "Critical")))) | J21: =G21+(1000-ROW())/1000000 | K21: =IF(C21>0, G21+ROW()/1000000, 9.99)
A22: =ROW() - 16 | B22: HR | C22: =COUNTIFS(Employee_KPI_Summary!$D$6:$D$93, B22, Employee_KPI_Summary!$F$6:$F$93, ">0") | D22: =SUMIFS(Employee_KPI_Summary!$F$6:$F$93, Employee_KPI_Summary!$D$6:$D$93, B22) | E22: =SUMIFS(Employee_KPI_Summary!$G$6:$G$93, Employee_KPI_Summary!$D$6:$D$93, B22) | F22: =SUMIFS(Employee_KPI_Summary!$H$6:$H$93, Employee_KPI_Summary!$D$6:$D$93, B22) | G22: =IF(D22>0, E22/D22, 0) | H22: =IF(SUMIFS(Employee_KPI_Summary!$K$6:$K$93, Employee_KPI_Summary!$D$6:$D$93, B22)>0, SUMIFS(Employee_KPI_Summary!$J$6:$J$93, Employee_KPI_Summary!$D$6:$D$93, B22)/SUMIFS(Employee_KPI_Summary!$K$6:$K$93, Employee_KPI_Summary!$D$6:$D$93, B22), 1.0) | I22: =IF(G22>=1.0, "Achieved", IF(G22>=0.75, "Good", IF(G22>=0.5, "Moderate", IF(G22>=0.25, "Low", "Critical")))) | J22: =G22+(1000-ROW())/1000000 | K22: =IF(C22>0, G22+ROW()/1000000, 9.99)
A23: =ROW() - 16 | B23: IT Support | C23: =COUNTIFS(Employee_KPI_Summary!$D$6:$D$93, B23, Employee_KPI_Summary!$F$6:$F$93, ">0") | D23: =SUMIFS(Employee_KPI_Summary!$F$6:$F$93, Employee_KPI_Summary!$D$6:$D$93, B23) | E23: =SUMIFS(Employee_KPI_Summary!$G$6:$G$93, Employee_KPI_Summary!$D$6:$D$93, B23) | F23: =SUMIFS(Employee_KPI_Summary!$H$6:$H$93, Employee_KPI_Summary!$D$6:$D$93, B23) | G23: =IF(D23>0, E23/D23, 0) | H23: =IF(SUMIFS(Employee_KPI_Summary!$K$6:$K$93, Employee_KPI_Summary!$D$6:$D$93, B23)>0, SUMIFS(Employee_KPI_Summary!$J$6:$J$93, Employee_KPI_Summary!$D$6:$D$93, B23)/SUMIFS(Employee_KPI_Summary!$K$6:$K$93, Employee_KPI_Summary!$D$6:$D$93, B23), 1.0) | I23: =IF(G23>=1.0, "Achieved", IF(G23>=0.75, "Good", IF(G23>=0.5, "Moderate", IF(G23>=0.25, "Low", "Critical")))) | J23: =G23+(1000-ROW())/1000000 | K23: =IF(C23>0, G23+ROW()/1000000, 9.99)
A24: =ROW() - 16 | B24: Maintenance | C24: =COUNTIFS(Employee_KPI_Summary!$D$6:$D$93, B24, Employee_KPI_Summary!$F$6:$F$93, ">0") | D24: =SUMIFS(Employee_KPI_Summary!$F$6:$F$93, Employee_KPI_Summary!$D$6:$D$93, B24) | E24: =SUMIFS(Employee_KPI_Summary!$G$6:$G$93, Employee_KPI_Summary!$D$6:$D$93, B24) | F24: =SUMIFS(Employee_KPI_Summary!$H$6:$H$93, Employee_KPI_Summary!$D$6:$D$93, B24) | G24: =IF(D24>0, E24/D24, 0) | H24: =IF(SUMIFS(Employee_KPI_Summary!$K$6:$K$93, Employee_KPI_Summary!$D$6:$D$93, B24)>0, SUMIFS(Employee_KPI_Summary!$J$6:$J$93, Employee_KPI_Summary!$D$6:$D$93, B24)/SUMIFS(Employee_KPI_Summary!$K$6:$K$93, Employee_KPI_Summary!$D$6:$D$93, B24), 1.0) | I24: =IF(G24>=1.0, "Achieved", IF(G24>=0.75, "Good", IF(G24>=0.5, "Moderate", IF(G24>=0.25, "Low", "Critical")))) | J24: =G24+(1000-ROW())/1000000 | K24: =IF(C24>0, G24+ROW()/1000000, 9.99)
A25: =ROW() - 16 | B25: Management | C25: =COUNTIFS(Employee_KPI_Summary!$D$6:$D$93, B25, Employee_KPI_Summary!$F$6:$F$93, ">0") | D25: =SUMIFS(Employee_KPI_Summary!$F$6:$F$93, Employee_KPI_Summary!$D$6:$D$93, B25) | E25: =SUMIFS(Employee_KPI_Summary!$G$6:$G$93, Employee_KPI_Summary!$D$6:$D$93, B25) | F25: =SUMIFS(Employee_KPI_Summary!$H$6:$H$93, Employee_KPI_Summary!$D$6:$D$93, B25) | G25: =IF(D25>0, E25/D25, 0) | H25: =IF(SUMIFS(Employee_KPI_Summary!$K$6:$K$93, Employee_KPI_Summary!$D$6:$D$93, B25)>0, SUMIFS(Employee_KPI_Summary!$J$6:$J$93, Employee_KPI_Summary!$D$6:$D$93, B25)/SUMIFS(Employee_KPI_Summary!$K$6:$K$93, Employee_KPI_Summary!$D$6:$D$93, B25), 1.0) | I25: =IF(G25>=1.0, "Achieved", IF(G25>=0.75, "Good", IF(G25>=0.5, "Moderate", IF(G25>=0.25, "Low", "Critical")))) | J25: =G25+(1000-ROW())/1000000 | K25: =IF(C25>0, G25+ROW()/1000000, 9.99)
A26: =ROW() - 16 | B26: Marketing | C26: =COUNTIFS(Employee_KPI_Summary!$D$6:$D$93, B26, Employee_KPI_Summary!$F$6:$F$93, ">0") | D26: =SUMIFS(Employee_KPI_Summary!$F$6:$F$93, Employee_KPI_Summary!$D$6:$D$93, B26) | E26: =SUMIFS(Employee_KPI_Summary!$G$6:$G$93, Employee_KPI_Summary!$D$6:$D$93, B26) | F26: =SUMIFS(Employee_KPI_Summary!$H$6:$H$93, Employee_KPI_Summary!$D$6:$D$93, B26) | G26: =IF(D26>0, E26/D26, 0) | H26: =IF(SUMIFS(Employee_KPI_Summary!$K$6:$K$93, Employee_KPI_Summary!$D$6:$D$93, B26)>0, SUMIFS(Employee_KPI_Summary!$J$6:$J$93, Employee_KPI_Summary!$D$6:$D$93, B26)/SUMIFS(Employee_KPI_Summary!$K$6:$K$93, Employee_KPI_Summary!$D$6:$D$93, B26), 1.0) | I26: =IF(G26>=1.0, "Achieved", IF(G26>=0.75, "Good", IF(G26>=0.5, "Moderate", IF(G26>=0.25, "Low", "Critical")))) | J26: =G26+(1000-ROW())/1000000 | K26: =IF(C26>0, G26+ROW()/1000000, 9.99)
A27: =ROW() - 16 | B27: NPD | C27: =COUNTIFS(Employee_KPI_Summary!$D$6:$D$93, B27, Employee_KPI_Summary!$F$6:$F$93, ">0") | D27: =SUMIFS(Employee_KPI_Summary!$F$6:$F$93, Employee_KPI_Summary!$D$6:$D$93, B27) | E27: =SUMIFS(Employee_KPI_Summary!$G$6:$G$93, Employee_KPI_Summary!$D$6:$D$93, B27) | F27: =SUMIFS(Employee_KPI_Summary!$H$6:$H$93, Employee_KPI_Summary!$D$6:$D$93, B27) | G27: =IF(D27>0, E27/D27, 0) | H27: =IF(SUMIFS(Employee_KPI_Summary!$K$6:$K$93, Employee_KPI_Summary!$D$6:$D$93, B27)>0, SUMIFS(Employee_KPI_Summary!$J$6:$J$93, Employee_KPI_Summary!$D$6:$D$93, B27)/SUMIFS(Employee_KPI_Summary!$K$6:$K$93, Employee_KPI_Summary!$D$6:$D$93, B27), 1.0) | I27: =IF(G27>=1.0, "Achieved", IF(G27>=0.75, "Good", IF(G27>=0.5, "Moderate", IF(G27>=0.25, "Low", "Critical")))) | J27: =G27+(1000-ROW())/1000000 | K27: =IF(C27>0, G27+ROW()/1000000, 9.99)
A28: =ROW() - 16 | B28: Operations | C28: =COUNTIFS(Employee_KPI_Summary!$D$6:$D$93, B28, Employee_KPI_Summary!$F$6:$F$93, ">0") | D28: =SUMIFS(Employee_KPI_Summary!$F$6:$F$93, Employee_KPI_Summary!$D$6:$D$93, B28) | E28: =SUMIFS(Employee_KPI_Summary!$G$6:$G$93, Employee_KPI_Summary!$D$6:$D$93, B28) | F28: =SUMIFS(Employee_KPI_Summary!$H$6:$H$93, Employee_KPI_Summary!$D$6:$D$93, B28) | G28: =IF(D28>0, E28/D28, 0) | H28: =IF(SUMIFS(Employee_KPI_Summary!$K$6:$K$93, Employee_KPI_Summary!$D$6:$D$93, B28)>0, SUMIFS(Employee_KPI_Summary!$J$6:$J$93, Employee_KPI_Summary!$D$6:$D$93, B28)/SUMIFS(Employee_KPI_Summary!$K$6:$K$93, Employee_KPI_Summary!$D$6:$D$93, B28), 1.0) | I28: =IF(G28>=1.0, "Achieved", IF(G28>=0.75, "Good", IF(G28>=0.5, "Moderate", IF(G28>=0.25, "Low", "Critical")))) | J28: =G28+(1000-ROW())/1000000 | K28: =IF(C28>0, G28+ROW()/1000000, 9.99)
... A33: =ROW() - 16 | B33: Stores | C33: =COUNTIFS(Employee_KPI_Summary!$D$6:$D$93, B33, Employee_KPI_Summary!$F$6:$F$93, ">0") | D33: =SUMIFS(Employee_KPI_Summary!$F$6:$F$93, Employee_KPI_Summary!$D$6:$D$93, B33) | E33: =SUMIFS(Employee_KPI_Summary!$G$6:$G$93, Employee_KPI_Summary!$D$6:$D$93, B33) | F33: =SUMIFS(Employee_KPI_Summary!$H$6:$H$93, Employee_KPI_Summary!$D$6:$D$93, B33) | G33: =IF(D33>0, E33/D33, 0) | H33: =IF(SUMIFS(Employee_KPI_Summary!$K$6:$K$93, Employee_KPI_Summary!$D$6:$D$93, B33)>0, SUMIFS(Employee_KPI_Summary!$J$6:$J$93, Employee_KPI_Summary!$D$6:$D$93, B33)/SUMIFS(Employee_KPI_Summary!$K$6:$K$93, Employee_KPI_Summary!$D$6:$D$93, B33), 1.0) | I33: =IF(G33>=1.0, "Achieved", IF(G33>=0.75, "Good", IF(G33>=0.5, "Moderate", IF(G33>=0.25, "Low", "Critical")))) | J33: =G33+(1000-ROW())/1000000 | K33: =IF(C33>0, G33+ROW()/1000000, 9.99)
B34: Total | C34: =SUM(C17:C33) | D34: =SUM(D17:D33) | E34: =SUM(E17:E33) | F34: =SUM(F17:F33) | G34: =IF(D34>0, E34/D34, 0) | H34: =IF(SUM(Employee_KPI_Summary!$K$6:$K$93)>0, SUM(Employee_KPI_Summary!$J$6:$J$93)/SUM(Employee_KPI_Summary!$K$6:$K$93), 1.0) | I34: =IF(G34>=1.0, "Achieved", IF(G34>=0.75, "Good", IF(G34>=0.5, "Moderate", IF(G34>=0.25, "Low", "Critical"))))
A37: Top Performing Departments | G37: Departments Requiring Attention
A38: Rank | B38: Department | C38: Achievement % | D38: Actual Hours | E38: Attendance % | G38: Department | H38: Remaining Hours | I38: Compliance % | J38: Risk Indicator
A39: 1 | B39: =INDEX($B$17:$B$33, MATCH(LARGE($J$17:$J$33, A39), $J$17:$J$33, 0)) | C39: =INDEX($G$17:$G$33, MATCH(LARGE($J$17:$J$33, A39), $J$17:$J$33, 0)) | D39: =INDEX($E$17:$E$33, MATCH(LARGE($J$17:$J$33, A39), $J$17:$J$33, 0)) | E39: =INDEX($H$17:$H$33, MATCH(LARGE($J$17:$J$33, A39), $J$17:$J$33, 0)) | G39: =INDEX($B$17:$B$33, MATCH(SMALL($K$17:$K$33, 1), $K$17:$K$33, 0)) | H39: =INDEX($F$17:$F$33, MATCH(SMALL($K$17:$K$33, 1), $K$17:$K$33, 0)) | I39: =INDEX($G$17:$G$33, MATCH(SMALL($K$17:$K$33, 1), $K$17:$K$33, 0)) | J39: =IF(I39<0.5, "🔴 Critical Risk", IF(I39<0.75, "🟡 Moderate Risk", "🟢 Low Risk"))
A40: 2 | B40: =INDEX($B$17:$B$33, MATCH(LARGE($J$17:$J$33, A40), $J$17:$J$33, 0)) | C40: =INDEX($G$17:$G$33, MATCH(LARGE($J$17:$J$33, A40), $J$17:$J$33, 0)) | D40: =INDEX($E$17:$E$33, MATCH(LARGE($J$17:$J$33, A40), $J$17:$J$33, 0)) | E40: =INDEX($H$17:$H$33, MATCH(LARGE($J$17:$J$33, A40), $J$17:$J$33, 0)) | G40: =INDEX($B$17:$B$33, MATCH(SMALL($K$17:$K$33, 2), $K$17:$K$33, 0)) | H40: =INDEX($F$17:$F$33, MATCH(SMALL($K$17:$K$33, 2), $K$17:$K$33, 0)) | I40: =INDEX($G$17:$G$33, MATCH(SMALL($K$17:$K$33, 2), $K$17:$K$33, 0)) | J40: =IF(I40<0.5, "🔴 Critical Risk", IF(I40<0.75, "🟡 Moderate Risk", "🟢 Low Risk"))
A41: 3 | B41: =INDEX($B$17:$B$33, MATCH(LARGE($J$17:$J$33, A41), $J$17:$J$33, 0)) | C41: =INDEX($G$17:$G$33, MATCH(LARGE($J$17:$J$33, A41), $J$17:$J$33, 0)) | D41: =INDEX($E$17:$E$33, MATCH(LARGE($J$17:$J$33, A41), $J$17:$J$33, 0)) | E41: =INDEX($H$17:$H$33, MATCH(LARGE($J$17:$J$33, A41), $J$17:$J$33, 0)) | G41: =INDEX($B$17:$B$33, MATCH(SMALL($K$17:$K$33, 3), $K$17:$K$33, 0)) | H41: =INDEX($F$17:$F$33, MATCH(SMALL($K$17:$K$33, 3), $K$17:$K$33, 0)) | I41: =INDEX($G$17:$G$33, MATCH(SMALL($K$17:$K$33, 3), $K$17:$K$33, 0)) | J41: =IF(I41<0.5, "🔴 Critical Risk", IF(I41<0.75, "🟡 Moderate Risk", "🟢 Low Risk"))
A42: 4 | B42: =INDEX($B$17:$B$33, MATCH(LARGE($J$17:$J$33, A42), $J$17:$J$33, 0)) | C42: =INDEX($G$17:$G$33, MATCH(LARGE($J$17:$J$33, A42), $J$17:$J$33, 0)) | D42: =INDEX($E$17:$E$33, MATCH(LARGE($J$17:$J$33, A42), $J$17:$J$33, 0)) | E42: =INDEX($H$17:$H$33, MATCH(LARGE($J$17:$J$33, A42), $J$17:$J$33, 0)) | G42: =INDEX($B$17:$B$33, MATCH(SMALL($K$17:$K$33, 4), $K$17:$K$33, 0)) | H42: =INDEX($F$17:$F$33, MATCH(SMALL($K$17:$K$33, 4), $K$17:$K$33, 0)) | I42: =INDEX($G$17:$G$33, MATCH(SMALL($K$17:$K$33, 4), $K$17:$K$33, 0)) | J42: =IF(I42<0.5, "🔴 Critical Risk", IF(I42<0.75, "🟡 Moderate Risk", "🟢 Low Risk"))
A43: 5 | B43: =INDEX($B$17:$B$33, MATCH(LARGE($J$17:$J$33, A43), $J$17:$J$33, 0)) | C43: =INDEX($G$17:$G$33, MATCH(LARGE($J$17:$J$33, A43), $J$17:$J$33, 0)) | D43: =INDEX($E$17:$E$33, MATCH(LARGE($J$17:$J$33, A43), $J$17:$J$33, 0)) | E43: =INDEX($H$17:$H$33, MATCH(LARGE($J$17:$J$33, A43), $J$17:$J$33, 0)) | G43: =INDEX($B$17:$B$33, MATCH(SMALL($K$17:$K$33, 5), $K$17:$K$33, 0)) | H43: =INDEX($F$17:$F$33, MATCH(SMALL($K$17:$K$33, 5), $K$17:$K$33, 0)) | I43: =INDEX($G$17:$G$33, MATCH(SMALL($K$17:$K$33, 5), $K$17:$K$33, 0)) | J43: =IF(I43<0.5, "🔴 Critical Risk", IF(I43<0.75, "🟡 Moderate Risk", "🟢 Low Risk"))
A46: Monthly Learning Trends (FY) | G46: Executive KPI Insights
A47: Month | B47: Target Hours | C47: Actual Hours | D47: Achievement %
A48: April | B48: =$A$11 * 1.33 | C48: =SUMIFS(Raw_Attendance_Data!$S$2:$S$3, Raw_Attendance_Data!$I$2:$I$3, A48, Raw_Attendance_Data!$A$2:$A$3, 1) | D48: =IF(B48>0, C48/B48, 0) | G48: ="• " & INDEX(B17:B33, MATCH(MAX(E17:E33), E17:E33, 0)) & " contributed the highest learning hours (" & TEXT(MAX(E17:E33), "#,##0") & " hours)."
A49: May | B49: =$A$11 * 1.33 | C49: =SUMIFS(Raw_Attendance_Data!$S$2:$S$3, Raw_Attendance_Data!$I$2:$I$3, A49, Raw_Attendance_Data!$A$2:$A$3, 1) | D49: =IF(B49>0, C49/B49, 0) | G49: ="• " & INDEX(B17:B33, MATCH(MIN(K17:K33), K17:K33, 0)) & " is " & TEXT(MAX(0, 1-MIN(K17:K33)), "0%") & " below annual learning target."
A50: June | B50: =$A$11 * 1.33 | C50: =SUMIFS(Raw_Attendance_Data!$S$2:$S$3, Raw_Attendance_Data!$I$2:$I$3, A50, Raw_Attendance_Data!$A$2:$A$3, 1) | D50: =IF(B50>0, C50/B50, 0) | G50: ="• " & INDEX(B17:B33, MATCH(MAX(G17:G33), G17:G33, 0)) & " achieved " & TEXT(MAX(G17:G33), "0.0%") & " learning compliance."
A51: July | B51: =$A$11 * 1.33 | C51: =SUMIFS(Raw_Attendance_Data!$S$2:$S$3, Raw_Attendance_Data!$I$2:$I$3, A51, Raw_Attendance_Data!$A$2:$A$3, 1) | D51: =IF(B51>0, C51/B51, 0) | G51: ="• Organization-wide learning completion stands at " & TEXT(A13, "0.0%") & "."
...

Sheet Employee_KPI_Summary
A1: Detailed Employee KPI Metrics & Compliance Status
A2: Do not edit this sheet directly. It contains formulas linking Employee metrics to the Dashboard filters.
A6: 1 | B6: 001 | C6: Sagar Ramesh | D6: QA | E6: Srinivasan Beeman | F6: =IF(AND(OR('Department KPI Analytics'!$G$6="All", D6='Department KPI Analytics'!$G$6), OR('Department KPI Analytics'!$E$8="All", E6='Department KPI Analytics'!$E$8)), 16, 0) | G6: =SUMIFS(Raw_Attendance_Data!$S$2:$S$3, Raw_Attendance_Data!$B$2:$B$3, B6, Raw_Attendance_Data!$A$2:$A$3, 1) | H6: =MAX(F6-G6, 0) | I6: =IF(F6>0, G6/F6, 0) | J6: =COUNTIFS(Raw_Attendance_Data!$B$2:$B$3, B6, Raw_Attendance_Data!$A$2:$A$3, 1, Raw_Attendance_Data!$Q$2:$Q$3, 1) | K6: =COUNTIFS(Raw_Attendance_Data!$B$2:$B$3, B6, Raw_Attendance_Data!$A$2:$A$3, 1) | L6: =IF(K6>0, J6/K6, 1.0)
A7: 2 | B7: 003 | C7: Megha Lakshmi Murugamani | D7: CRM | E7: Prakash Padukhone Muthiah | F7: =IF(AND(OR('Department KPI Analytics'!$G$6="All", D7='Department KPI Analytics'!$G$6), OR('Department KPI Analytics'!$E$8="All", E7='Department KPI Analytics'!$E$8)), 16, 0) | G7: =SUMIFS(Raw_Attendance_Data!$S$2:$S$3, Raw_Attendance_Data!$B$2:$B$3, B7, Raw_Attendance_Data!$A$2:$A$3, 1) | H7: =MAX(F7-G7, 0) | I7: =IF(F7>0, G7/F7, 0) | J7: =COUNTIFS(Raw_Attendance_Data!$B$2:$B$3, B7, Raw_Attendance_Data!$A$2:$A$3, 1, Raw_Attendance_Data!$Q$2:$Q$3, 1) | K7: =COUNTIFS(Raw_Attendance_Data!$B$2:$B$3, B7, Raw_Attendance_Data!$A$2:$A$3, 1) | L7: =IF(K7>0, J7/K7, 1.0)
A8: 3 | B8: 005 | C8: Arunkumar Selvaraj | D8: RFQ | E8: R Rathina Kumar | F8: =IF(AND(OR('Department KPI Analytics'!$G$6="All", D8='Department KPI Analytics'!$G$6), OR('Department KPI Analytics'!$E$8="All", E8='Department KPI Analytics'!$E$8)), 16, 0) | G8: =SUMIFS(Raw_Attendance_Data!$S$2:$S$3, Raw_Attendance_Data!$B$2:$B$3, B8, Raw_Attendance_Data!$A$2:$A$3, 1) | H8: =MAX(F8-G8, 0) | I8: =IF(F8>0, G8/F8, 0) | J8: =COUNTIFS(Raw_Attendance_Data!$B$2:$B$3, B8, Raw_Attendance_Data!$A$2:$A$3, 1, Raw_Attendance_Data!$Q$2:$Q$3, 1) | K8: =COUNTIFS(Raw_Attendance_Data!$B$2:$B$3, B8, Raw_Attendance_Data!$A$2:$A$3, 1) | L8: =IF(K8>0, J8/K8, 1.0)
A9: 4 | B9: 006 | C9: Nalini Vasudevan | D9: Stores | E9: Sakthivel Muthu | F9: =IF(AND(OR('Department KPI Analytics'!$G$6="All", D9='Department KPI Analytics'!$G$6), OR('Department KPI Analytics'!$E$8="All", E9='Department KPI Analytics'!$E$8)), 16, 0) | G9: =SUMIFS(Raw_Attendance_Data!$S$2:$S$3, Raw_Attendance_Data!$B$2:$B$3, B9, Raw_Attendance_Data!$A$2:$A$3, 1) | H9: =MAX(F9-G9, 0) | I9: =IF(F9>0, G9/F9, 0) | J9: =COUNTIFS(Raw_Attendance_Data!$B$2:$B$3, B9, Raw_Attendance_Data!$A$2:$A$3, 1, Raw_Attendance_Data!$Q$2:$Q$3, 1) | K9: =COUNTIFS(Raw_Attendance_Data!$B$2:$B$3, B9, Raw_Attendance_Data!$A$2:$A$3, 1) | L9: =IF(K9>0, J9/K9, 1.0)
A10: 5 | B10: 007 | C10: Naveenkumar M | D10: NPD | E10: Prakash Padukhone Muthiah | F10: =IF(AND(OR('Department KPI Analytics'!$G$6="All", D10='Department KPI Analytics'!$G$6), OR('Department KPI Analytics'!$E$8="All", E10='Department KPI Analytics'!$E$8)), 16, 0) | G10: =SUMIFS(Raw_Attendance_Data!$S$2:$S$3, Raw_Attendance_Data!$B$2:$B$3, B10, Raw_Attendance_Data!$A$2:$A$3, 1) | H10: =MAX(F10-G10, 0) | I10: =IF(F10>0, G10/F10, 0) | J10: =COUNTIFS(Raw_Attendance_Data!$B$2:$B$3, B10, Raw_Attendance_Data!$A$2:$A$3, 1, Raw_Attendance_Data!$Q$2:$Q$3, 1) | K10: =COUNTIFS(Raw_Attendance_Data!$B$2:$B$3, B10, Raw_Attendance_Data!$A$2:$A$3, 1) | L10: =IF(K10>0, J10/K10, 1.0)
A11: 6 | B11: 008 | C11: Nethaji Raja | D11: QA | E11: R Rathina Kumar | F11: =IF(AND(OR('Department KPI Analytics'!$G$6="All", D11='Department KPI Analytics'!$G$6), OR('Department KPI Analytics'!$E$8="All", E11='Department KPI Analytics'!$E$8)), 16, 0) | G11: =SUMIFS(Raw_Attendance_Data!$S$2:$S$3, Raw_Attendance_Data!$B$2:$B$3, B11, Raw_Attendance_Data!$A$2:$A$3, 1) | H11: =MAX(F11-G11, 0) | I11: =IF(F11>0, G11/F11, 0) | J11: =COUNTIFS(Raw_Attendance_Data!$B$2:$B$3, B11, Raw_Attendance_Data!$A$2:$A$3, 1, Raw_Attendance_Data!$Q$2:$Q$3, 1) | K11: =COUNTIFS(Raw_Attendance_Data!$B$2:$B$3, B11, Raw_Attendance_Data!$A$2:$A$3, 1) | L11: =IF(K11>0, J11/K11, 1.0)
A12: 7 | B12: 011 | C12: Mariyaruban Mariyakilaimans | D12: Accounts | E12: Arunachalam Palaniappan | F12: =IF(AND(OR('Department KPI Analytics'!$G$6="All", D12='Department KPI Analytics'!$G$6), OR('Department KPI Analytics'!$E$8="All", E12='Department KPI Analytics'!$E$8)), 16, 0) | G12: =SUMIFS(Raw_Attendance_Data!$S$2:$S$3, Raw_Attendance_Data!$B$2:$B$3, B12, Raw_Attendance_Data!$A$2:$A$3, 1) | H12: =MAX(F12-G12, 0) | I12: =IF(F12>0, G12/F12, 0) | J12: =COUNTIFS(Raw_Attendance_Data!$B$2:$B$3, B12, Raw_Attendance_Data!$A$2:$A$3, 1, Raw_Attendance_Data!$Q$2:$Q$3, 1) | K12: =COUNTIFS(Raw_Attendance_Data!$B$2:$B$3, B12, Raw_Attendance_Data!$A$2:$A$3, 1) | L12: =IF(K12>0, J12/K12, 1.0)
A13: 8 | B13: 013 | C13: Govindammal . | D13: QA | E13: Srinivasan Beeman | F13: =IF(AND(OR('Department KPI Analytics'!$G$6="All", D13='Department KPI Analytics'!$G$6), OR('Department KPI Analytics'!$E$8="All", E13='Department KPI Analytics'!$E$8)), 16, 0) | G13: =SUMIFS(Raw_Attendance_Data!$S$2:$S$3, Raw_Attendance_Data!$B$2:$B$3, B13, Raw_Attendance_Data!$A$2:$A$3, 1) | H13: =MAX(F13-G13, 0) | I13: =IF(F13>0, G13/F13, 0) | J13: =COUNTIFS(Raw_Attendance_Data!$B$2:$B$3, B13, Raw_Attendance_Data!$A$2:$A$3, 1, Raw_Attendance_Data!$Q$2:$Q$3, 1) | K13: =COUNTIFS(Raw_Attendance_Data!$B$2:$B$3, B13, Raw_Attendance_Data!$A$2:$A$3, 1) | L13: =IF(K13>0, J13/K13, 1.0)
A14: 9 | B14: 015 | C14: Sangeetha Murugan | D14: QA | E14: Srinivasan Beeman | F14: =IF(AND(OR('Department KPI Analytics'!$G$6="All", D14='Department KPI Analytics'!$G$6), OR('Department KPI Analytics'!$E$8="All", E14='Department KPI Analytics'!$E$8)), 16, 0) | G14: =SUMIFS(Raw_Attendance_Data!$S$2:$S$3, Raw_Attendance_Data!$B$2:$B$3, B14, Raw_Attendance_Data!$A$2:$A$3, 1) | H14: =MAX(F14-G14, 0) | I14: =IF(F14>0, G14/F14, 0) | J14: =COUNTIFS(Raw_Attendance_Data!$B$2:$B$3, B14, Raw_Attendance_Data!$A$2:$A$3, 1, Raw_Attendance_Data!$Q$2:$Q$3, 1) | K14: =COUNTIFS(Raw_Attendance_Data!$B$2:$B$3, B14, Raw_Attendance_Data!$A$2:$A$3, 1) | L14: =IF(K14>0, J14/K14, 1.0)
A15: 10 | B15: 016 | C15: Gunasekaran Kaveri Setty | D15: QA | E15: Srinivasan Beeman | F15: =IF(AND(OR('Department KPI Analytics'!$G$6="All", D15='Department KPI Analytics'!$G$6), OR('Department KPI Analytics'!$E$8="All", E15='Department KPI Analytics'!$E$8)), 16, 0) | G15: =SUMIFS(Raw_Attendance_Data!$S$2:$S$3, Raw_Attendance_Data!$B$2:$B$3, B15, Raw_Attendance_Data!$A$2:$A$3, 1) | H15: =MAX(F15-G15, 0) | I15: =IF(F15>0, G15/F15, 0) | J15: =COUNTIFS(Raw_Attendance_Data!$B$2:$B$3, B15, Raw_Attendance_Data!$A$2:$A$3, 1, Raw_Attendance_Data!$Q$2:$Q$3, 1) | K15: =COUNTIFS(Raw_Attendance_Data!$B$2:$B$3, B15, Raw_Attendance_Data!$A$2:$A$3, 1) | L15: =IF(K15>0, J15/K15, 1.0)
A16: 11 | B16: 017 | C16: Saravana Hanumanthappa | D16: IT Support | E16: Manasa R | F16: =IF(AND(OR('Department KPI Analytics'!$G$6="All", D16='Department KPI Analytics'!$G$6), OR('Department KPI Analytics'!$E$8="All", E16='Department KPI Analytics'!$E$8)), 16, 0) | G16: =SUMIFS(Raw_Attendance_Data!$S$2:$S$3, Raw_Attendance_Data!$B$2:$B$3, B16, Raw_Attendance_Data!$A$2:$A$3, 1) | H16: =MAX(F16-G16, 0) | I16: =IF(F16>0, G16/F16, 0) | J16: =COUNTIFS(Raw_Attendance_Data!$B$2:$B$3, B16, Raw_Attendance_Data!$A$2:$A$3, 1, Raw_Attendance_Data!$Q$2:$Q$3, 1) | K16: =COUNTIFS(Raw_Attendance_Data!$B$2:$B$3, B16, Raw_Attendance_Data!$A$2:$A$3, 1) | L16: =IF(K16>0, J16/K16, 1.0)
A17: 12 | B17: 018 | C17: Perumal Govindharaj | D17: QA | E17: Srinivasan Beeman | F17: =IF(AND(OR('Department KPI Analytics'!$G$6="All", D17='Department KPI Analytics'!$G$6), OR('Department KPI Analytics'!$E$8="All", E17='Department KPI Analytics'!$E$8)), 16, 0) | G17: =SUMIFS(Raw_Attendance_Data!$S$2:$S$3, Raw_Attendance_Data!$B$2:$B$3, B17, Raw_Attendance_Data!$A$2:$A$3, 1) | H17: =MAX(F17-G17, 0) | I17: =IF(F17>0, G17/F17, 0) | J17: =COUNTIFS(Raw_Attendance_Data!$B$2:$B$3, B17, Raw_Attendance_Data!$A$2:$A$3, 1, Raw_Attendance_Data!$Q$2:$Q$3, 1) | K17: =COUNTIFS(Raw_Attendance_Data!$B$2:$B$3, B17, Raw_Attendance_Data!$A$2:$A$3, 1) | L17: =IF(K17>0, J17/K17, 1.0)
... A90: 85 | B90: DUMMY-PRAKASH | C90: Prakash Padukhone Muthiah | D90: Operations | E90: Nitin R Patel | F90: =IF(AND(OR('Department KPI Analytics'!$G$6="All", D90='Department KPI Analytics'!$G$6), OR('Department KPI Analytics'!$E$8="All", E90='Department KPI Analytics'!$E$8)), 16, 0) | G90: =SUMIFS(Raw_Attendance_Data!$S$2:$S$3, Raw_Attendance_Data!$B$2:$B$3, B90, Raw_Attendance_Data!$A$2:$A$3, 1) | H90: =MAX(F90-G90, 0) | I90: =IF(F90>0, G90/F90, 0) | J90: =COUNTIFS(Raw_Attendance_Data!$B$2:$B$3, B90, Raw_Attendance_Data!$A$2:$A$3, 1, Raw_Attendance_Data!$Q$2:$Q$3, 1) | K90: =COUNTIFS(Raw_Attendance_Data!$B$2:$B$3, B90, Raw_Attendance_Data!$A$2:$A$3, 1) | L90: =IF(K90>0, J90/K90, 1.0)
A91: 86 | B91: MGR001 | C91: Team Manager | D91: Management | F91: =IF(AND(OR('Department KPI Analytics'!$G$6="All", D91='Department KPI Analytics'!$G$6), OR('Department KPI Analytics'!$E$8="All", E91='Department KPI Analytics'!$E$8)), 16, 0) | G91: =SUMIFS(Raw_Attendance_Data!$S$2:$S$3, Raw_Attendance_Data!$B$2:$B$3, B91, Raw_Attendance_Data!$A$2:$A$3, 1) | H91: =MAX(F91-G91, 0) | I91: =IF(F91>0, G91/F91, 0) | J91: =COUNTIFS(Raw_Attendance_Data!$B$2:$B$3, B91, Raw_Attendance_Data!$A$2:$A$3, 1, Raw_Attendance_Data!$Q$2:$Q$3, 1) | K91: =COUNTIFS(Raw_Attendance_Data!$B$2:$B$3, B91, Raw_Attendance_Data!$A$2:$A$3, 1) | L91: =IF(K91>0, J91/K91, 1.0)
A92: 87 | B92: SGS-KET | C92: Ketan BC | D92: Management | E92: Team Manager | F92: =IF(AND(OR('Department KPI Analytics'!$G$6="All", D92='Department KPI Analytics'!$G$6), OR('Department KPI Analytics'!$E$8="All", E92='Department KPI Analytics'!$E$8)), 16, 0) | G92: =SUMIFS(Raw_Attendance_Data!$S$2:$S$3, Raw_Attendance_Data!$B$2:$B$3, B92, Raw_Attendance_Data!$A$2:$A$3, 1) | H92: =MAX(F92-G92, 0) | I92: =IF(F92>0, G92/F92, 0) | J92: =COUNTIFS(Raw_Attendance_Data!$B$2:$B$3, B92, Raw_Attendance_Data!$A$2:$A$3, 1, Raw_Attendance_Data!$Q$2:$Q$3, 1) | K92: =COUNTIFS(Raw_Attendance_Data!$B$2:$B$3, B92, Raw_Attendance_Data!$A$2:$A$3, 1) | L92: =IF(K92>0, J92/K92, 1.0)
A93: 88 | B93: SGS-NIT | C93: Nitin R Patel | D93: Management | E93: Team Manager | F93: =IF(AND(OR('Department KPI Analytics'!$G$6="All", D93='Department KPI Analytics'!$G$6), OR('Department KPI Analytics'!$E$8="All", E93='Department KPI Analytics'!$E$8)), 16, 0) | G93: =SUMIFS(Raw_Attendance_Data!$S$2:$S$3, Raw_Attendance_Data!$B$2:$B$3, B93, Raw_Attendance_Data!$A$2:$A$3, 1) | H93: =MAX(F93-G93, 0) | I93: =IF(F93>0, G93/F93, 0) | J93: =COUNTIFS(Raw_Attendance_Data!$B$2:$B$3, B93, Raw_Attendance_Data!$A$2:$A$3, 1, Raw_Attendance_Data!$Q$2:$Q$3, 1) | K93: =COUNTIFS(Raw_Attendance_Data!$B$2:$B$3, B93, Raw_Attendance_Data!$A$2:$A$3, 1) | L93: =IF(K93>0, J93/K93, 1.0)

Sheet Raw_Attendance_Data
A1: Matches_Filter | B1: Employee Code | C1: Employee Name | D1: Department | E1: Manager | F1: Training Date | G1: Financial Year | H1: Quarter | I1: Month Name | J1: Training Title | K1: Training Category | L1: Training Type | M1: Attendance Status | N1: Actual Hours | O1: Max Hours | P1: Is_Unique_Training | Q1: Is_Attended_Present | R1: Is_Completed | S1: Actual Hours Credit
A2: =IF(AND(OR('Department KPI Analytics'!$B$6="All", G2='Department KPI Analytics'!$B$6), OR('Department KPI Analytics'!$D$6="All", H2='Department KPI Analytics'!$D$6), OR('Department KPI Analytics'!$E$6="All", I2='Department KPI Analytics'!$E$6), OR('Department KPI Analytics'!$G$6="All", D2='Department KPI Analytics'!$G$6), OR('Department KPI Analytics'!$B$8="All", K2='Department KPI Analytics'!$B$8), OR('Department KPI Analytics'!$E$8="All", E2='Department KPI Analytics'!$E$8), OR('Department KPI Analytics'!$H$8="All", L2='Department KPI Analytics'!$H$8)), 1, 0) | B2: 100 | C2: Nagaraju K | D2: QA | E2: Srinivasan Beeman | F2: 2026-06-03 | G2: 2026-2027 | H2: Q1 | I2: June | J2: Communication | K2: Soft Skills | L2: INTERNAL | M2: PRESENT | N2: 0.5 | O2: 0.5 | P2: =IF(AND(A2=1, COUNTIFS($J$2:J2, J2, $A$2:A2, 1)=1), 1, 0) | Q2: =IF(AND(A2=1, OR(M2="PRESENT", M2="LATE")), 1, 0) | R2: 1 | S2: =IF(AND(Q2=1, R2=1), N2, 0)
A3: =IF(AND(OR('Department KPI Analytics'!$B$6="All", G3='Department KPI Analytics'!$B$6), OR('Department KPI Analytics'!$D$6="All", H3='Department KPI Analytics'!$D$6), OR('Department KPI Analytics'!$E$6="All", I3='Department KPI Analytics'!$E$6), OR('Department KPI Analytics'!$G$6="All", D3='Department KPI Analytics'!$G$6), OR('Department KPI Analytics'!$B$8="All", K3='Department KPI Analytics'!$B$8), OR('Department KPI Analytics'!$E$8="All", E3='Department KPI Analytics'!$E$8), OR('Department KPI Analytics'!$H$8="All", L3='Department KPI Analytics'!$H$8)), 1, 0) | B3: 100 | C3: Nagaraju K | D3: QA | E3: Srinivasan Beeman | F3: 2026-06-13 | G3: 2026-2027 | H3: Q1 | I3: June | J3: Communication Training | K3: HR & People | L3: INTERNAL | M3: PRESENT | N3: 0.5 | O3: 0.5 | P3: =IF(AND(A3=1, COUNTIFS($J$2:J3, J3, $A$2:A3, 1)=1), 1, 0) | Q3: =IF(AND(A3=1, OR(M3="PRESENT", M3="LATE")), 1, 0) | R3: 1 | S3: =IF(AND(Q3=1, R3=1), N3, 0)

Sheet Filter_Lists
A1: Financial Years | B1: Quarters | C1: Months | D1: Departments | E1: Categories | F1: Managers | G1: Training Types
A2: All | B2: All | C2: All | D2: All | E2: All | F2: All | G2: All
A3: 2026-2027 | B3: Q1 | C3: April | D3: Accounts | E3: Compliance & Safety | F3: Anil Kumar Joshi | G3: INTERNAL
B4: Q2 | C4: May | D4: Casting | E4: Finance & Accounting | F4: Arunachalam Palaniappan | G4: EXTERNAL
B5: Q3 | C5: June | D5: Commercial | E5: HR & People | F5: Harsora Rajan Bakulbhai | G5: ONLINE
B6: Q4 | C6: July | D6: CRM | E6: Leadership & Management | F6: Ketan BC | G6: WORKSHOP
C7: August | D7: Driver | E7: Product & Domain | F7: Manasa R | G7: CERTIFICATION
C8: September | D8: HR | E8: Sales & Customer Service | F8: Naveenkumar M
C9: October | D9: IT Support | E9: Soft Skills | F9: Nethaji Raja
C10: November | D10: Maintenance | E10: Technical Skills | F10: Nitin R Patel
C11: December | D11: Management | F11: Prakash Padukhone Muthiah
C12: January | D12: Marketing | F12: R Rathina Kumar
C13: February | D13: NPD | F13: Rajeshwari Ganeshkumar
C14: March | D14: Operations | F14: Sakthivel Muthu
D15: Purchase Castings | F15: Sakthivel Muthu
D16: QA | F16: Srinivasan Beeman
D17: RFQ | F17: Sundaravel S
D18: Sourcing | F18: Swetha Swetha
D19: Stores | F19: Team Manager
F20: Vinit Praful Karia
